Watching for file changes with StatReloader
Internal Server Error: /face_swap/
"POST /face_swap/ HTTP/1.1" 500 94
Internal Server Error: /face_swap/
"POST /face_swap/ HTTP/1.1" 500 94
"POST /template/add/ HTTP/1.1" 200 46
"POST /face_swap/ HTTP/1.1" 200 375
Internal Server Error: /face_swap/
"POST /face_swap/ HTTP/1.1" 500 94
D:\Projects\faceswap_rest_api\face_api\node\views.py changed, reloading.
Watching for file changes with StatReloader
D:\Projects\faceswap_rest_api\face_api\node\views.py changed, reloading.
Watching for file changes with StatReloader
D:\Projects\faceswap_rest_api\face_api\node\views.py changed, reloading.
Watching for file changes with StatReloader
D:\Projects\faceswap_rest_api\face_api\node\views.py changed, reloading.
Watching for file changes with StatReloader
D:\Projects\faceswap_rest_api\face_api\node\views.py changed, reloading.
Watching for file changes with StatReloader
D:\Projects\faceswap_rest_api\face_api\node\views.py changed, reloading.
Watching for file changes with StatReloader
Internal Server Error: /face_swap/
Traceback (most recent call last):
  File "D:\Projects\faceswap_rest_api\face_api\venv\Lib\site-packages\django\core\handlers\exception.py", line 55, in inner
    response = get_response(request)
               ^^^^^^^^^^^^^^^^^^^^^
  File "D:\Projects\faceswap_rest_api\face_api\venv\Lib\site-packages\django\core\handlers\base.py", line 197, in _get_response
    response = wrapped_callback(request, *callback_args, **callback_kwargs)
               ^^^^^^^^^^^^^^^^^^^^^^^^^^^^^^^^^^^^^^^^^^^^^^^^^^^^^^^^^^^^
  File "D:\Projects\faceswap_rest_api\face_api\venv\Lib\site-packages\django\views\decorators\csrf.py", line 65, in _view_wrapper
    return view_func(request, *args, **kwargs)
           ^^^^^^^^^^^^^^^^^^^^^^^^^^^^^^^^^^^
  File "D:\Projects\faceswap_rest_api\face_api\venv\Lib\site-packages\django\views\generic\base.py", line 104, in view
    return self.dispatch(request, *args, **kwargs)
           ^^^^^^^^^^^^^^^^^^^^^^^^^^^^^^^^^^^^^^^
  File "D:\Projects\faceswap_rest_api\face_api\venv\Lib\site-packages\rest_framework\views.py", line 509, in dispatch
    response = self.handle_exception(exc)
               ^^^^^^^^^^^^^^^^^^^^^^^^^^
  File "D:\Projects\faceswap_rest_api\face_api\venv\Lib\site-packages\rest_framework\views.py", line 469, in handle_exception
    self.raise_uncaught_exception(exc)
  File "D:\Projects\faceswap_rest_api\face_api\venv\Lib\site-packages\rest_framework\views.py", line 480, in raise_uncaught_exception
    raise exc
  File "D:\Projects\faceswap_rest_api\face_api\venv\Lib\site-packages\rest_framework\views.py", line 506, in dispatch
    response = handler(request, *args, **kwargs)
               ^^^^^^^^^^^^^^^^^^^^^^^^^^^^^^^^^
  File "D:\Projects\faceswap_rest_api\face_api\venv\Lib\site-packages\rest_framework\decorators.py", line 50, in handler
    return func(*args, **kwargs)
           ^^^^^^^^^^^^^^^^^^^^^
  File "D:\Projects\faceswap_rest_api\face_api\node\views.py", line 81, in post_face_swap
    template_app_obj = templateApp2.objects.get(id=template_id)
                       ^^^^^^^^^^^^^^^^^^^^^^^^^^^^^^^^^^^^^^^^
  File "D:\Projects\faceswap_rest_api\face_api\venv\Lib\site-packages\django\db\models\manager.py", line 87, in manager_method
    return getattr(self.get_queryset(), name)(*args, **kwargs)
           ^^^^^^^^^^^^^^^^^^^^^^^^^^^^^^^^^^^^^^^^^^^^^^^^^^^
  File "D:\Projects\faceswap_rest_api\face_api\venv\Lib\site-packages\django\db\models\query.py", line 649, in get
    raise self.model.DoesNotExist(
node.models.templateApp2.DoesNotExist: templateApp2 matching query does not exist.
"POST /face_swap/ HTTP/1.1" 500 124664
D:\Projects\faceswap_rest_api\face_api\node\views.py changed, reloading.
Watching for file changes with StatReloader
Internal Server Error: /face_swap/
Traceback (most recent call last):
  File "D:\Projects\faceswap_rest_api\face_api\venv\Lib\site-packages\django\core\handlers\exception.py", line 55, in inner
    response = get_response(request)
               ^^^^^^^^^^^^^^^^^^^^^
  File "D:\Projects\faceswap_rest_api\face_api\venv\Lib\site-packages\django\core\handlers\base.py", line 197, in _get_response
    response = wrapped_callback(request, *callback_args, **callback_kwargs)
               ^^^^^^^^^^^^^^^^^^^^^^^^^^^^^^^^^^^^^^^^^^^^^^^^^^^^^^^^^^^^
  File "D:\Projects\faceswap_rest_api\face_api\venv\Lib\site-packages\django\views\decorators\csrf.py", line 65, in _view_wrapper
    return view_func(request, *args, **kwargs)
           ^^^^^^^^^^^^^^^^^^^^^^^^^^^^^^^^^^^
  File "D:\Projects\faceswap_rest_api\face_api\venv\Lib\site-packages\django\views\generic\base.py", line 104, in view
    return self.dispatch(request, *args, **kwargs)
           ^^^^^^^^^^^^^^^^^^^^^^^^^^^^^^^^^^^^^^^
  File "D:\Projects\faceswap_rest_api\face_api\venv\Lib\site-packages\rest_framework\views.py", line 509, in dispatch
    response = self.handle_exception(exc)
               ^^^^^^^^^^^^^^^^^^^^^^^^^^
  File "D:\Projects\faceswap_rest_api\face_api\venv\Lib\site-packages\rest_framework\views.py", line 469, in handle_exception
    self.raise_uncaught_exception(exc)
  File "D:\Projects\faceswap_rest_api\face_api\venv\Lib\site-packages\rest_framework\views.py", line 480, in raise_uncaught_exception
    raise exc
  File "D:\Projects\faceswap_rest_api\face_api\venv\Lib\site-packages\rest_framework\views.py", line 506, in dispatch
    response = handler(request, *args, **kwargs)
               ^^^^^^^^^^^^^^^^^^^^^^^^^^^^^^^^^
  File "D:\Projects\faceswap_rest_api\face_api\venv\Lib\site-packages\rest_framework\decorators.py", line 50, in handler
    return func(*args, **kwargs)
           ^^^^^^^^^^^^^^^^^^^^^
  File "D:\Projects\faceswap_rest_api\face_api\node\views.py", line 81, in post_face_swap
    template_app_obj = templateApp2.objects.get(sort_id=template_id)
                       ^^^^^^^^^^^^^^^^^^^^^^^^^^^^^^^^^^^^^^^^^^
  File "D:\Projects\faceswap_rest_api\face_api\venv\Lib\site-packages\django\db\models\manager.py", line 87, in manager_method
    return getattr(self.get_queryset(), name)(*args, **kwargs)
           ^^^^^^^^^^^^^^^^^^^^^^^^^^^^^^^^^^^^^^^^^^^^^^^^^^^
  File "D:\Projects\faceswap_rest_api\face_api\venv\Lib\site-packages\django\db\models\query.py", line 635, in get
    clone = self._chain() if self.query.combinator else self.filter(*args, **kwargs)
                                                        ^^^^^^^^^^^^^^^^^^^^^^^^^^^^
  File "D:\Projects\faceswap_rest_api\face_api\venv\Lib\site-packages\django\db\models\query.py", line 1476, in filter
    return self._filter_or_exclude(False, args, kwargs)
           ^^^^^^^^^^^^^^^^^^^^^^^^^^^^^^^^^^^^^^^^^^^^
  File "D:\Projects\faceswap_rest_api\face_api\venv\Lib\site-packages\django\db\models\query.py", line 1494, in _filter_or_exclude
    clone._filter_or_exclude_inplace(negate, args, kwargs)
  File "D:\Projects\faceswap_rest_api\face_api\venv\Lib\site-packages\django\db\models\query.py", line 1501, in _filter_or_exclude_inplace
    self._query.add_q(Q(*args, **kwargs))
  File "D:\Projects\faceswap_rest_api\face_api\venv\Lib\site-packages\django\db\models\sql\query.py", line 1613, in add_q
    clause, _ = self._add_q(q_object, self.used_aliases)
                ^^^^^^^^^^^^^^^^^^^^^^^^^^^^^^^^^^^^^^^^
  File "D:\Projects\faceswap_rest_api\face_api\venv\Lib\site-packages\django\db\models\sql\query.py", line 1645, in _add_q
    child_clause, needed_inner = self.build_filter(
                                 ^^^^^^^^^^^^^^^^^^
  File "D:\Projects\faceswap_rest_api\face_api\venv\Lib\site-packages\django\db\models\sql\query.py", line 1495, in build_filter
    lookups, parts, reffed_expression = self.solve_lookup_type(arg, summarize)
                                        ^^^^^^^^^^^^^^^^^^^^^^^^^^^^^^^^^^^^^^
  File "D:\Projects\faceswap_rest_api\face_api\venv\Lib\site-packages\django\db\models\sql\query.py", line 1307, in solve_lookup_type
    _, field, _, lookup_parts = self.names_to_path(lookup_splitted, self.get_meta())
                                ^^^^^^^^^^^^^^^^^^^^^^^^^^^^^^^^^^^^^^^^^^^^^^^^^^^^
  File "D:\Projects\faceswap_rest_api\face_api\venv\Lib\site-packages\django\db\models\sql\query.py", line 1772, in names_to_path
    raise FieldError(
django.core.exceptions.FieldError: Cannot resolve keyword 'sort' into field. Choices are: id, premium, preview_source, sort_id, source, thumb
"POST /face_swap/ HTTP/1.1" 500 164862
D:\Projects\faceswap_rest_api\face_api\node\views.py changed, reloading.
Watching for file changes with StatReloader
"POST /face_swap/ HTTP/1.1" 200 373
D:\Projects\faceswap_rest_api\face_api\node\views.py changed, reloading.
Watching for file changes with StatReloader
D:\Projects\faceswap_rest_api\face_api\node\views.py changed, reloading.
Watching for file changes with StatReloader
D:\Projects\faceswap_rest_api\face_api\node\views.py changed, reloading.
Watching for file changes with StatReloader
Watching for file changes with StatReloader
Watching for file changes with StatReloader
Watching for file changes with StatReloader
Watching for file changes with StatReloader
Internal Server Error: /template/add/
Traceback (most recent call last):
  File "D:\Projects\faceswap_rest_api\face_api\venv\Lib\site-packages\urllib3\connection.py", line 198, in _new_conn
    sock = connection.create_connection(
           ^^^^^^^^^^^^^^^^^^^^^^^^^^^^^
  File "D:\Projects\faceswap_rest_api\face_api\venv\Lib\site-packages\urllib3\util\connection.py", line 60, in create_connection
    for res in socket.getaddrinfo(host, port, family, socket.SOCK_STREAM):
               ^^^^^^^^^^^^^^^^^^^^^^^^^^^^^^^^^^^^^^^^^^^^^^^^^^^^^^^^^^
  File "C:\Users\Volodia\AppData\Local\Programs\Python\Python311\Lib\socket.py", line 962, in getaddrinfo
    for res in _socket.getaddrinfo(host, port, family, type, proto, flags):
               ^^^^^^^^^^^^^^^^^^^^^^^^^^^^^^^^^^^^^^^^^^^^^^^^^^^^^^^^^^^
socket.gaierror: [Errno 11001] getaddrinfo failed

The above exception was the direct cause of the following exception:

Traceback (most recent call last):
  File "D:\Projects\faceswap_rest_api\face_api\venv\Lib\site-packages\urllib3\connectionpool.py", line 793, in urlopen
    response = self._make_request(
               ^^^^^^^^^^^^^^^^^^^
  File "D:\Projects\faceswap_rest_api\face_api\venv\Lib\site-packages\urllib3\connectionpool.py", line 491, in _make_request
    raise new_e
  File "D:\Projects\faceswap_rest_api\face_api\venv\Lib\site-packages\urllib3\connectionpool.py", line 467, in _make_request
    self._validate_conn(conn)
  File "D:\Projects\faceswap_rest_api\face_api\venv\Lib\site-packages\urllib3\connectionpool.py", line 1099, in _validate_conn
    conn.connect()
  File "D:\Projects\faceswap_rest_api\face_api\venv\Lib\site-packages\urllib3\connection.py", line 616, in connect
    self.sock = sock = self._new_conn()
                       ^^^^^^^^^^^^^^^^
  File "D:\Projects\faceswap_rest_api\face_api\venv\Lib\site-packages\urllib3\connection.py", line 205, in _new_conn
    raise NameResolutionError(self.host, self, e) from e
urllib3.exceptions.NameResolutionError: <urllib3.connection.HTTPSConnection object at 0x000002C089342810>: Failed to resolve 'fs2template.nikb-contact-us.workers.devdata' ([Errno 11001] getaddrinfo failed)

The above exception was the direct cause of the following exception:

Traceback (most recent call last):
  File "D:\Projects\faceswap_rest_api\face_api\venv\Lib\site-packages\requests\adapters.py", line 486, in send
    resp = conn.urlopen(
           ^^^^^^^^^^^^^
  File "D:\Projects\faceswap_rest_api\face_api\venv\Lib\site-packages\urllib3\connectionpool.py", line 847, in urlopen
    retries = retries.increment(
              ^^^^^^^^^^^^^^^^^^
  File "D:\Projects\faceswap_rest_api\face_api\venv\Lib\site-packages\urllib3\util\retry.py", line 515, in increment
    raise MaxRetryError(_pool, url, reason) from reason  # type: ignore[arg-type]
    ^^^^^^^^^^^^^^^^^^^^^^^^^^^^^^^^^^^^^^^^^^^^^^^^^^^
urllib3.exceptions.MaxRetryError: HTTPSConnectionPool(host='fs2template.nikb-contact-us.workers.devdata', port=443): Max retries exceeded with url: /source/4.png (Caused by NameResolutionError("<urllib3.connection.HTTPSConnection object at 0x000002C089342810>: Failed to resolve 'fs2template.nikb-contact-us.workers.devdata' ([Errno 11001] getaddrinfo failed)"))

During handling of the above exception, another exception occurred:

Traceback (most recent call last):
  File "D:\Projects\faceswap_rest_api\face_api\venv\Lib\site-packages\django\core\handlers\exception.py", line 55, in inner
    response = get_response(request)
               ^^^^^^^^^^^^^^^^^^^^^
  File "D:\Projects\faceswap_rest_api\face_api\venv\Lib\site-packages\django\core\handlers\base.py", line 197, in _get_response
    response = wrapped_callback(request, *callback_args, **callback_kwargs)
               ^^^^^^^^^^^^^^^^^^^^^^^^^^^^^^^^^^^^^^^^^^^^^^^^^^^^^^^^^^^^
  File "D:\Projects\faceswap_rest_api\face_api\venv\Lib\site-packages\django\views\decorators\csrf.py", line 65, in _view_wrapper
    return view_func(request, *args, **kwargs)
           ^^^^^^^^^^^^^^^^^^^^^^^^^^^^^^^^^^^
  File "D:\Projects\faceswap_rest_api\face_api\venv\Lib\site-packages\django\views\generic\base.py", line 104, in view
    return self.dispatch(request, *args, **kwargs)
           ^^^^^^^^^^^^^^^^^^^^^^^^^^^^^^^^^^^^^^^
  File "D:\Projects\faceswap_rest_api\face_api\venv\Lib\site-packages\rest_framework\views.py", line 509, in dispatch
    response = self.handle_exception(exc)
               ^^^^^^^^^^^^^^^^^^^^^^^^^^
  File "D:\Projects\faceswap_rest_api\face_api\venv\Lib\site-packages\rest_framework\views.py", line 469, in handle_exception
    self.raise_uncaught_exception(exc)
  File "D:\Projects\faceswap_rest_api\face_api\venv\Lib\site-packages\rest_framework\views.py", line 480, in raise_uncaught_exception
    raise exc
  File "D:\Projects\faceswap_rest_api\face_api\venv\Lib\site-packages\rest_framework\views.py", line 506, in dispatch
    response = handler(request, *args, **kwargs)
               ^^^^^^^^^^^^^^^^^^^^^^^^^^^^^^^^^
  File "D:\Projects\faceswap_rest_api\face_api\venv\Lib\site-packages\rest_framework\decorators.py", line 50, in handler
    return func(*args, **kwargs)
           ^^^^^^^^^^^^^^^^^^^^^
  File "D:\Projects\faceswap_rest_api\face_api\node\views.py", line 330, in post_template
    CDN_OBJ.upload_to_cdn(re.sub(r'^(\.\/)', '', decode_source_path))
  File "D:\Projects\faceswap_rest_api\face_api\node\cdn_manager.py", line 52, in upload_to_cdn
    response = requests.put(
               ^^^^^^^^^^^^^
  File "D:\Projects\faceswap_rest_api\face_api\venv\Lib\site-packages\requests\api.py", line 130, in put
    return request("put", url, data=data, **kwargs)
           ^^^^^^^^^^^^^^^^^^^^^^^^^^^^^^^^^^^^^^^^
  File "D:\Projects\faceswap_rest_api\face_api\venv\Lib\site-packages\requests\api.py", line 59, in request
    return session.request(method=method, url=url, **kwargs)
           ^^^^^^^^^^^^^^^^^^^^^^^^^^^^^^^^^^^^^^^^^^^^^^^^^
  File "D:\Projects\faceswap_rest_api\face_api\venv\Lib\site-packages\requests\sessions.py", line 589, in request
    resp = self.send(prep, **send_kwargs)
           ^^^^^^^^^^^^^^^^^^^^^^^^^^^^^^
  File "D:\Projects\faceswap_rest_api\face_api\venv\Lib\site-packages\requests\sessions.py", line 703, in send
    r = adapter.send(request, **kwargs)
        ^^^^^^^^^^^^^^^^^^^^^^^^^^^^^^^
  File "D:\Projects\faceswap_rest_api\face_api\venv\Lib\site-packages\requests\adapters.py", line 519, in send
    raise ConnectionError(e, request=request)
requests.exceptions.ConnectionError: HTTPSConnectionPool(host='fs2template.nikb-contact-us.workers.devdata', port=443): Max retries exceeded with url: /source/4.png (Caused by NameResolutionError("<urllib3.connection.HTTPSConnection object at 0x000002C089342810>: Failed to resolve 'fs2template.nikb-contact-us.workers.devdata' ([Errno 11001] getaddrinfo failed)"))
"POST /template/add/ HTTP/1.1" 500 207448
Internal Server Error: /template/add/
Traceback (most recent call last):
  File "D:\Projects\faceswap_rest_api\face_api\venv\Lib\site-packages\urllib3\connection.py", line 198, in _new_conn
    sock = connection.create_connection(
           ^^^^^^^^^^^^^^^^^^^^^^^^^^^^^
  File "D:\Projects\faceswap_rest_api\face_api\venv\Lib\site-packages\urllib3\util\connection.py", line 60, in create_connection
    for res in socket.getaddrinfo(host, port, family, socket.SOCK_STREAM):
               ^^^^^^^^^^^^^^^^^^^^^^^^^^^^^^^^^^^^^^^^^^^^^^^^^^^^^^^^^^
  File "C:\Users\Volodia\AppData\Local\Programs\Python\Python311\Lib\socket.py", line 962, in getaddrinfo
    for res in _socket.getaddrinfo(host, port, family, type, proto, flags):
               ^^^^^^^^^^^^^^^^^^^^^^^^^^^^^^^^^^^^^^^^^^^^^^^^^^^^^^^^^^^
socket.gaierror: [Errno 11001] getaddrinfo failed

The above exception was the direct cause of the following exception:

Traceback (most recent call last):
  File "D:\Projects\faceswap_rest_api\face_api\venv\Lib\site-packages\urllib3\connectionpool.py", line 793, in urlopen
    response = self._make_request(
               ^^^^^^^^^^^^^^^^^^^
  File "D:\Projects\faceswap_rest_api\face_api\venv\Lib\site-packages\urllib3\connectionpool.py", line 491, in _make_request
    raise new_e
  File "D:\Projects\faceswap_rest_api\face_api\venv\Lib\site-packages\urllib3\connectionpool.py", line 467, in _make_request
    self._validate_conn(conn)
  File "D:\Projects\faceswap_rest_api\face_api\venv\Lib\site-packages\urllib3\connectionpool.py", line 1099, in _validate_conn
    conn.connect()
  File "D:\Projects\faceswap_rest_api\face_api\venv\Lib\site-packages\urllib3\connection.py", line 616, in connect
    self.sock = sock = self._new_conn()
                       ^^^^^^^^^^^^^^^^
  File "D:\Projects\faceswap_rest_api\face_api\venv\Lib\site-packages\urllib3\connection.py", line 205, in _new_conn
    raise NameResolutionError(self.host, self, e) from e
urllib3.exceptions.NameResolutionError: <urllib3.connection.HTTPSConnection object at 0x000002C089288590>: Failed to resolve 'fs2template.nikb-contact-us.workers.devdata' ([Errno 11001] getaddrinfo failed)

The above exception was the direct cause of the following exception:

Traceback (most recent call last):
  File "D:\Projects\faceswap_rest_api\face_api\venv\Lib\site-packages\requests\adapters.py", line 486, in send
    resp = conn.urlopen(
           ^^^^^^^^^^^^^
  File "D:\Projects\faceswap_rest_api\face_api\venv\Lib\site-packages\urllib3\connectionpool.py", line 847, in urlopen
    retries = retries.increment(
              ^^^^^^^^^^^^^^^^^^
  File "D:\Projects\faceswap_rest_api\face_api\venv\Lib\site-packages\urllib3\util\retry.py", line 515, in increment
    raise MaxRetryError(_pool, url, reason) from reason  # type: ignore[arg-type]
    ^^^^^^^^^^^^^^^^^^^^^^^^^^^^^^^^^^^^^^^^^^^^^^^^^^^
urllib3.exceptions.MaxRetryError: HTTPSConnectionPool(host='fs2template.nikb-contact-us.workers.devdata', port=443): Max retries exceeded with url: /source/4.png (Caused by NameResolutionError("<urllib3.connection.HTTPSConnection object at 0x000002C089288590>: Failed to resolve 'fs2template.nikb-contact-us.workers.devdata' ([Errno 11001] getaddrinfo failed)"))

During handling of the above exception, another exception occurred:

Traceback (most recent call last):
  File "D:\Projects\faceswap_rest_api\face_api\venv\Lib\site-packages\django\core\handlers\exception.py", line 55, in inner
    response = get_response(request)
               ^^^^^^^^^^^^^^^^^^^^^
  File "D:\Projects\faceswap_rest_api\face_api\venv\Lib\site-packages\django\core\handlers\base.py", line 197, in _get_response
    response = wrapped_callback(request, *callback_args, **callback_kwargs)
               ^^^^^^^^^^^^^^^^^^^^^^^^^^^^^^^^^^^^^^^^^^^^^^^^^^^^^^^^^^^^
  File "D:\Projects\faceswap_rest_api\face_api\venv\Lib\site-packages\django\views\decorators\csrf.py", line 65, in _view_wrapper
    return view_func(request, *args, **kwargs)
           ^^^^^^^^^^^^^^^^^^^^^^^^^^^^^^^^^^^
  File "D:\Projects\faceswap_rest_api\face_api\venv\Lib\site-packages\django\views\generic\base.py", line 104, in view
    return self.dispatch(request, *args, **kwargs)
           ^^^^^^^^^^^^^^^^^^^^^^^^^^^^^^^^^^^^^^^
  File "D:\Projects\faceswap_rest_api\face_api\venv\Lib\site-packages\rest_framework\views.py", line 509, in dispatch
    response = self.handle_exception(exc)
               ^^^^^^^^^^^^^^^^^^^^^^^^^^
  File "D:\Projects\faceswap_rest_api\face_api\venv\Lib\site-packages\rest_framework\views.py", line 469, in handle_exception
    self.raise_uncaught_exception(exc)
  File "D:\Projects\faceswap_rest_api\face_api\venv\Lib\site-packages\rest_framework\views.py", line 480, in raise_uncaught_exception
    raise exc
  File "D:\Projects\faceswap_rest_api\face_api\venv\Lib\site-packages\rest_framework\views.py", line 506, in dispatch
    response = handler(request, *args, **kwargs)
               ^^^^^^^^^^^^^^^^^^^^^^^^^^^^^^^^^
  File "D:\Projects\faceswap_rest_api\face_api\venv\Lib\site-packages\rest_framework\decorators.py", line 50, in handler
    return func(*args, **kwargs)
           ^^^^^^^^^^^^^^^^^^^^^
  File "D:\Projects\faceswap_rest_api\face_api\node\views.py", line 330, in post_template
    CDN_OBJ.upload_to_cdn(re.sub(r'^(\.\/)', '', decode_source_path))
  File "D:\Projects\faceswap_rest_api\face_api\node\cdn_manager.py", line 52, in upload_to_cdn
    response = requests.put(
               ^^^^^^^^^^^^^
  File "D:\Projects\faceswap_rest_api\face_api\venv\Lib\site-packages\requests\api.py", line 130, in put
    return request("put", url, data=data, **kwargs)
           ^^^^^^^^^^^^^^^^^^^^^^^^^^^^^^^^^^^^^^^^
  File "D:\Projects\faceswap_rest_api\face_api\venv\Lib\site-packages\requests\api.py", line 59, in request
    return session.request(method=method, url=url, **kwargs)
           ^^^^^^^^^^^^^^^^^^^^^^^^^^^^^^^^^^^^^^^^^^^^^^^^^
  File "D:\Projects\faceswap_rest_api\face_api\venv\Lib\site-packages\requests\sessions.py", line 589, in request
    resp = self.send(prep, **send_kwargs)
           ^^^^^^^^^^^^^^^^^^^^^^^^^^^^^^
  File "D:\Projects\faceswap_rest_api\face_api\venv\Lib\site-packages\requests\sessions.py", line 703, in send
    r = adapter.send(request, **kwargs)
        ^^^^^^^^^^^^^^^^^^^^^^^^^^^^^^^
  File "D:\Projects\faceswap_rest_api\face_api\venv\Lib\site-packages\requests\adapters.py", line 519, in send
    raise ConnectionError(e, request=request)
requests.exceptions.ConnectionError: HTTPSConnectionPool(host='fs2template.nikb-contact-us.workers.devdata', port=443): Max retries exceeded with url: /source/4.png (Caused by NameResolutionError("<urllib3.connection.HTTPSConnection object at 0x000002C089288590>: Failed to resolve 'fs2template.nikb-contact-us.workers.devdata' ([Errno 11001] getaddrinfo failed)"))
"POST /template/add/ HTTP/1.1" 500 207448
Not Found: /
"GET / HTTP/1.1" 404 2867
Not Found: /favicon.ico
"GET /favicon.ico HTTP/1.1" 404 2918
Watching for file changes with StatReloader
Not Found: /
"GET / HTTP/1.1" 404 2867
"GET /admin/ HTTP/1.1" 302 0
"GET /admin/login/?next=/admin/ HTTP/1.1" 200 4158
"GET /static/admin/css/base.css HTTP/1.1" 200 21544
"GET /static/admin/css/login.css HTTP/1.1" 200 958
"GET /static/admin/css/nav_sidebar.css HTTP/1.1" 200 2810
"GET /static/admin/css/dark_mode.css HTTP/1.1" 200 2682
"GET /static/admin/js/nav_sidebar.js HTTP/1.1" 200 3063
"GET /static/admin/css/responsive.css HTTP/1.1" 200 17905
"GET /static/admin/js/theme.js HTTP/1.1" 200 1943
Not Found: /
"GET / HTTP/1.1" 404 2867
Internal Server Error: /template/add/
Traceback (most recent call last):
  File "D:\Projects\faceswap_rest_api\face_api\venv\Lib\site-packages\urllib3\connection.py", line 198, in _new_conn
    sock = connection.create_connection(
           ^^^^^^^^^^^^^^^^^^^^^^^^^^^^^
  File "D:\Projects\faceswap_rest_api\face_api\venv\Lib\site-packages\urllib3\util\connection.py", line 60, in create_connection
    for res in socket.getaddrinfo(host, port, family, socket.SOCK_STREAM):
               ^^^^^^^^^^^^^^^^^^^^^^^^^^^^^^^^^^^^^^^^^^^^^^^^^^^^^^^^^^
  File "C:\Users\Volodia\AppData\Local\Programs\Python\Python311\Lib\socket.py", line 962, in getaddrinfo
    for res in _socket.getaddrinfo(host, port, family, type, proto, flags):
               ^^^^^^^^^^^^^^^^^^^^^^^^^^^^^^^^^^^^^^^^^^^^^^^^^^^^^^^^^^^
socket.gaierror: [Errno 11001] getaddrinfo failed

The above exception was the direct cause of the following exception:

Traceback (most recent call last):
  File "D:\Projects\faceswap_rest_api\face_api\venv\Lib\site-packages\urllib3\connectionpool.py", line 793, in urlopen
    response = self._make_request(
               ^^^^^^^^^^^^^^^^^^^
  File "D:\Projects\faceswap_rest_api\face_api\venv\Lib\site-packages\urllib3\connectionpool.py", line 491, in _make_request
    raise new_e
  File "D:\Projects\faceswap_rest_api\face_api\venv\Lib\site-packages\urllib3\connectionpool.py", line 467, in _make_request
    self._validate_conn(conn)
  File "D:\Projects\faceswap_rest_api\face_api\venv\Lib\site-packages\urllib3\connectionpool.py", line 1099, in _validate_conn
    conn.connect()
  File "D:\Projects\faceswap_rest_api\face_api\venv\Lib\site-packages\urllib3\connection.py", line 616, in connect
    self.sock = sock = self._new_conn()
                       ^^^^^^^^^^^^^^^^
  File "D:\Projects\faceswap_rest_api\face_api\venv\Lib\site-packages\urllib3\connection.py", line 205, in _new_conn
    raise NameResolutionError(self.host, self, e) from e
urllib3.exceptions.NameResolutionError: <urllib3.connection.HTTPSConnection object at 0x000001C61EB83610>: Failed to resolve 'fs2template.nikb-contact-us.workers.devdata' ([Errno 11001] getaddrinfo failed)

The above exception was the direct cause of the following exception:

Traceback (most recent call last):
  File "D:\Projects\faceswap_rest_api\face_api\venv\Lib\site-packages\requests\adapters.py", line 486, in send
    resp = conn.urlopen(
           ^^^^^^^^^^^^^
  File "D:\Projects\faceswap_rest_api\face_api\venv\Lib\site-packages\urllib3\connectionpool.py", line 847, in urlopen
    retries = retries.increment(
              ^^^^^^^^^^^^^^^^^^
  File "D:\Projects\faceswap_rest_api\face_api\venv\Lib\site-packages\urllib3\util\retry.py", line 515, in increment
    raise MaxRetryError(_pool, url, reason) from reason  # type: ignore[arg-type]
    ^^^^^^^^^^^^^^^^^^^^^^^^^^^^^^^^^^^^^^^^^^^^^^^^^^^
urllib3.exceptions.MaxRetryError: HTTPSConnectionPool(host='fs2template.nikb-contact-us.workers.devdata', port=443): Max retries exceeded with url: /source/4.png (Caused by NameResolutionError("<urllib3.connection.HTTPSConnection object at 0x000001C61EB83610>: Failed to resolve 'fs2template.nikb-contact-us.workers.devdata' ([Errno 11001] getaddrinfo failed)"))

During handling of the above exception, another exception occurred:

Traceback (most recent call last):
  File "D:\Projects\faceswap_rest_api\face_api\venv\Lib\site-packages\django\core\handlers\exception.py", line 55, in inner
    response = get_response(request)
               ^^^^^^^^^^^^^^^^^^^^^
  File "D:\Projects\faceswap_rest_api\face_api\venv\Lib\site-packages\django\core\handlers\base.py", line 197, in _get_response
    response = wrapped_callback(request, *callback_args, **callback_kwargs)
               ^^^^^^^^^^^^^^^^^^^^^^^^^^^^^^^^^^^^^^^^^^^^^^^^^^^^^^^^^^^^
  File "D:\Projects\faceswap_rest_api\face_api\venv\Lib\site-packages\django\views\decorators\csrf.py", line 65, in _view_wrapper
    return view_func(request, *args, **kwargs)
           ^^^^^^^^^^^^^^^^^^^^^^^^^^^^^^^^^^^
  File "D:\Projects\faceswap_rest_api\face_api\venv\Lib\site-packages\django\views\generic\base.py", line 104, in view
    return self.dispatch(request, *args, **kwargs)
           ^^^^^^^^^^^^^^^^^^^^^^^^^^^^^^^^^^^^^^^
  File "D:\Projects\faceswap_rest_api\face_api\venv\Lib\site-packages\rest_framework\views.py", line 509, in dispatch
    response = self.handle_exception(exc)
               ^^^^^^^^^^^^^^^^^^^^^^^^^^
  File "D:\Projects\faceswap_rest_api\face_api\venv\Lib\site-packages\rest_framework\views.py", line 469, in handle_exception
    self.raise_uncaught_exception(exc)
  File "D:\Projects\faceswap_rest_api\face_api\venv\Lib\site-packages\rest_framework\views.py", line 480, in raise_uncaught_exception
    raise exc
  File "D:\Projects\faceswap_rest_api\face_api\venv\Lib\site-packages\rest_framework\views.py", line 506, in dispatch
    response = handler(request, *args, **kwargs)
               ^^^^^^^^^^^^^^^^^^^^^^^^^^^^^^^^^
  File "D:\Projects\faceswap_rest_api\face_api\venv\Lib\site-packages\rest_framework\decorators.py", line 50, in handler
    return func(*args, **kwargs)
           ^^^^^^^^^^^^^^^^^^^^^
  File "D:\Projects\faceswap_rest_api\face_api\node\views.py", line 330, in post_template
    CDN_OBJ.upload_to_cdn(re.sub(r'^(\.\/)', '', decode_source_path))
  File "D:\Projects\faceswap_rest_api\face_api\node\cdn_manager.py", line 52, in upload_to_cdn
    response = requests.put(
               ^^^^^^^^^^^^^
  File "D:\Projects\faceswap_rest_api\face_api\venv\Lib\site-packages\requests\api.py", line 130, in put
    return request("put", url, data=data, **kwargs)
           ^^^^^^^^^^^^^^^^^^^^^^^^^^^^^^^^^^^^^^^^
  File "D:\Projects\faceswap_rest_api\face_api\venv\Lib\site-packages\requests\api.py", line 59, in request
    return session.request(method=method, url=url, **kwargs)
           ^^^^^^^^^^^^^^^^^^^^^^^^^^^^^^^^^^^^^^^^^^^^^^^^^
  File "D:\Projects\faceswap_rest_api\face_api\venv\Lib\site-packages\requests\sessions.py", line 589, in request
    resp = self.send(prep, **send_kwargs)
           ^^^^^^^^^^^^^^^^^^^^^^^^^^^^^^
  File "D:\Projects\faceswap_rest_api\face_api\venv\Lib\site-packages\requests\sessions.py", line 703, in send
    r = adapter.send(request, **kwargs)
        ^^^^^^^^^^^^^^^^^^^^^^^^^^^^^^^
  File "D:\Projects\faceswap_rest_api\face_api\venv\Lib\site-packages\requests\adapters.py", line 519, in send
    raise ConnectionError(e, request=request)
requests.exceptions.ConnectionError: HTTPSConnectionPool(host='fs2template.nikb-contact-us.workers.devdata', port=443): Max retries exceeded with url: /source/4.png (Caused by NameResolutionError("<urllib3.connection.HTTPSConnection object at 0x000001C61EB83610>: Failed to resolve 'fs2template.nikb-contact-us.workers.devdata' ([Errno 11001] getaddrinfo failed)"))
"POST /template/add/ HTTP/1.1" 500 207449
"POST /check/faces HTTP/1.1" 200 11
Internal Server Error: /template/add/
Traceback (most recent call last):
  File "D:\Projects\faceswap_rest_api\face_api\venv\Lib\site-packages\urllib3\connection.py", line 198, in _new_conn
    sock = connection.create_connection(
           ^^^^^^^^^^^^^^^^^^^^^^^^^^^^^
  File "D:\Projects\faceswap_rest_api\face_api\venv\Lib\site-packages\urllib3\util\connection.py", line 60, in create_connection
    for res in socket.getaddrinfo(host, port, family, socket.SOCK_STREAM):
               ^^^^^^^^^^^^^^^^^^^^^^^^^^^^^^^^^^^^^^^^^^^^^^^^^^^^^^^^^^
  File "C:\Users\Volodia\AppData\Local\Programs\Python\Python311\Lib\socket.py", line 962, in getaddrinfo
    for res in _socket.getaddrinfo(host, port, family, type, proto, flags):
               ^^^^^^^^^^^^^^^^^^^^^^^^^^^^^^^^^^^^^^^^^^^^^^^^^^^^^^^^^^^
socket.gaierror: [Errno 11001] getaddrinfo failed

The above exception was the direct cause of the following exception:

Traceback (most recent call last):
  File "D:\Projects\faceswap_rest_api\face_api\venv\Lib\site-packages\urllib3\connectionpool.py", line 793, in urlopen
    response = self._make_request(
               ^^^^^^^^^^^^^^^^^^^
  File "D:\Projects\faceswap_rest_api\face_api\venv\Lib\site-packages\urllib3\connectionpool.py", line 491, in _make_request
    raise new_e
  File "D:\Projects\faceswap_rest_api\face_api\venv\Lib\site-packages\urllib3\connectionpool.py", line 467, in _make_request
    self._validate_conn(conn)
  File "D:\Projects\faceswap_rest_api\face_api\venv\Lib\site-packages\urllib3\connectionpool.py", line 1099, in _validate_conn
    conn.connect()
  File "D:\Projects\faceswap_rest_api\face_api\venv\Lib\site-packages\urllib3\connection.py", line 616, in connect
    self.sock = sock = self._new_conn()
                       ^^^^^^^^^^^^^^^^
  File "D:\Projects\faceswap_rest_api\face_api\venv\Lib\site-packages\urllib3\connection.py", line 205, in _new_conn
    raise NameResolutionError(self.host, self, e) from e
urllib3.exceptions.NameResolutionError: <urllib3.connection.HTTPSConnection object at 0x000001C61EB8D150>: Failed to resolve 'fs2template.nikb-contact-us.workers.devdata' ([Errno 11001] getaddrinfo failed)

The above exception was the direct cause of the following exception:

Traceback (most recent call last):
  File "D:\Projects\faceswap_rest_api\face_api\venv\Lib\site-packages\requests\adapters.py", line 486, in send
    resp = conn.urlopen(
           ^^^^^^^^^^^^^
  File "D:\Projects\faceswap_rest_api\face_api\venv\Lib\site-packages\urllib3\connectionpool.py", line 847, in urlopen
    retries = retries.increment(
              ^^^^^^^^^^^^^^^^^^
  File "D:\Projects\faceswap_rest_api\face_api\venv\Lib\site-packages\urllib3\util\retry.py", line 515, in increment
    raise MaxRetryError(_pool, url, reason) from reason  # type: ignore[arg-type]
    ^^^^^^^^^^^^^^^^^^^^^^^^^^^^^^^^^^^^^^^^^^^^^^^^^^^
urllib3.exceptions.MaxRetryError: HTTPSConnectionPool(host='fs2template.nikb-contact-us.workers.devdata', port=443): Max retries exceeded with url: /source/4.jpg (Caused by NameResolutionError("<urllib3.connection.HTTPSConnection object at 0x000001C61EB8D150>: Failed to resolve 'fs2template.nikb-contact-us.workers.devdata' ([Errno 11001] getaddrinfo failed)"))

During handling of the above exception, another exception occurred:

Traceback (most recent call last):
  File "D:\Projects\faceswap_rest_api\face_api\venv\Lib\site-packages\django\core\handlers\exception.py", line 55, in inner
    response = get_response(request)
               ^^^^^^^^^^^^^^^^^^^^^
  File "D:\Projects\faceswap_rest_api\face_api\venv\Lib\site-packages\django\core\handlers\base.py", line 197, in _get_response
    response = wrapped_callback(request, *callback_args, **callback_kwargs)
               ^^^^^^^^^^^^^^^^^^^^^^^^^^^^^^^^^^^^^^^^^^^^^^^^^^^^^^^^^^^^
  File "D:\Projects\faceswap_rest_api\face_api\venv\Lib\site-packages\django\views\decorators\csrf.py", line 65, in _view_wrapper
    return view_func(request, *args, **kwargs)
           ^^^^^^^^^^^^^^^^^^^^^^^^^^^^^^^^^^^
  File "D:\Projects\faceswap_rest_api\face_api\venv\Lib\site-packages\django\views\generic\base.py", line 104, in view
    return self.dispatch(request, *args, **kwargs)
           ^^^^^^^^^^^^^^^^^^^^^^^^^^^^^^^^^^^^^^^
  File "D:\Projects\faceswap_rest_api\face_api\venv\Lib\site-packages\rest_framework\views.py", line 509, in dispatch
    response = self.handle_exception(exc)
               ^^^^^^^^^^^^^^^^^^^^^^^^^^
  File "D:\Projects\faceswap_rest_api\face_api\venv\Lib\site-packages\rest_framework\views.py", line 469, in handle_exception
    self.raise_uncaught_exception(exc)
  File "D:\Projects\faceswap_rest_api\face_api\venv\Lib\site-packages\rest_framework\views.py", line 480, in raise_uncaught_exception
    raise exc
  File "D:\Projects\faceswap_rest_api\face_api\venv\Lib\site-packages\rest_framework\views.py", line 506, in dispatch
    response = handler(request, *args, **kwargs)
               ^^^^^^^^^^^^^^^^^^^^^^^^^^^^^^^^^
  File "D:\Projects\faceswap_rest_api\face_api\venv\Lib\site-packages\rest_framework\decorators.py", line 50, in handler
    return func(*args, **kwargs)
           ^^^^^^^^^^^^^^^^^^^^^
  File "D:\Projects\faceswap_rest_api\face_api\node\views.py", line 330, in post_template
    CDN_OBJ.upload_to_cdn(re.sub(r'^(\.\/)', '', decode_source_path))
  File "D:\Projects\faceswap_rest_api\face_api\node\cdn_manager.py", line 52, in upload_to_cdn
    response = requests.put(
               ^^^^^^^^^^^^^
  File "D:\Projects\faceswap_rest_api\face_api\venv\Lib\site-packages\requests\api.py", line 130, in put
    return request("put", url, data=data, **kwargs)
           ^^^^^^^^^^^^^^^^^^^^^^^^^^^^^^^^^^^^^^^^
  File "D:\Projects\faceswap_rest_api\face_api\venv\Lib\site-packages\requests\api.py", line 59, in request
    return session.request(method=method, url=url, **kwargs)
           ^^^^^^^^^^^^^^^^^^^^^^^^^^^^^^^^^^^^^^^^^^^^^^^^^
  File "D:\Projects\faceswap_rest_api\face_api\venv\Lib\site-packages\requests\sessions.py", line 589, in request
    resp = self.send(prep, **send_kwargs)
           ^^^^^^^^^^^^^^^^^^^^^^^^^^^^^^
  File "D:\Projects\faceswap_rest_api\face_api\venv\Lib\site-packages\requests\sessions.py", line 703, in send
    r = adapter.send(request, **kwargs)
        ^^^^^^^^^^^^^^^^^^^^^^^^^^^^^^^
  File "D:\Projects\faceswap_rest_api\face_api\venv\Lib\site-packages\requests\adapters.py", line 519, in send
    raise ConnectionError(e, request=request)
requests.exceptions.ConnectionError: HTTPSConnectionPool(host='fs2template.nikb-contact-us.workers.devdata', port=443): Max retries exceeded with url: /source/4.jpg (Caused by NameResolutionError("<urllib3.connection.HTTPSConnection object at 0x000001C61EB8D150>: Failed to resolve 'fs2template.nikb-contact-us.workers.devdata' ([Errno 11001] getaddrinfo failed)"))
"POST /template/add/ HTTP/1.1" 500 207407
Internal Server Error: /template/add/
Traceback (most recent call last):
  File "D:\Projects\faceswap_rest_api\face_api\venv\Lib\site-packages\urllib3\connection.py", line 198, in _new_conn
    sock = connection.create_connection(
           ^^^^^^^^^^^^^^^^^^^^^^^^^^^^^
  File "D:\Projects\faceswap_rest_api\face_api\venv\Lib\site-packages\urllib3\util\connection.py", line 60, in create_connection
    for res in socket.getaddrinfo(host, port, family, socket.SOCK_STREAM):
               ^^^^^^^^^^^^^^^^^^^^^^^^^^^^^^^^^^^^^^^^^^^^^^^^^^^^^^^^^^
  File "C:\Users\Volodia\AppData\Local\Programs\Python\Python311\Lib\socket.py", line 962, in getaddrinfo
    for res in _socket.getaddrinfo(host, port, family, type, proto, flags):
               ^^^^^^^^^^^^^^^^^^^^^^^^^^^^^^^^^^^^^^^^^^^^^^^^^^^^^^^^^^^
socket.gaierror: [Errno 11001] getaddrinfo failed

The above exception was the direct cause of the following exception:

Traceback (most recent call last):
  File "D:\Projects\faceswap_rest_api\face_api\venv\Lib\site-packages\urllib3\connectionpool.py", line 793, in urlopen
    response = self._make_request(
               ^^^^^^^^^^^^^^^^^^^
  File "D:\Projects\faceswap_rest_api\face_api\venv\Lib\site-packages\urllib3\connectionpool.py", line 491, in _make_request
    raise new_e
  File "D:\Projects\faceswap_rest_api\face_api\venv\Lib\site-packages\urllib3\connectionpool.py", line 467, in _make_request
    self._validate_conn(conn)
  File "D:\Projects\faceswap_rest_api\face_api\venv\Lib\site-packages\urllib3\connectionpool.py", line 1099, in _validate_conn
    conn.connect()
  File "D:\Projects\faceswap_rest_api\face_api\venv\Lib\site-packages\urllib3\connection.py", line 616, in connect
    self.sock = sock = self._new_conn()
                       ^^^^^^^^^^^^^^^^
  File "D:\Projects\faceswap_rest_api\face_api\venv\Lib\site-packages\urllib3\connection.py", line 205, in _new_conn
    raise NameResolutionError(self.host, self, e) from e
urllib3.exceptions.NameResolutionError: <urllib3.connection.HTTPSConnection object at 0x000001C618BF3210>: Failed to resolve 'fs2template.nikb-contact-us.workers.devdata' ([Errno 11001] getaddrinfo failed)

The above exception was the direct cause of the following exception:

Traceback (most recent call last):
  File "D:\Projects\faceswap_rest_api\face_api\venv\Lib\site-packages\requests\adapters.py", line 486, in send
    resp = conn.urlopen(
           ^^^^^^^^^^^^^
  File "D:\Projects\faceswap_rest_api\face_api\venv\Lib\site-packages\urllib3\connectionpool.py", line 847, in urlopen
    retries = retries.increment(
              ^^^^^^^^^^^^^^^^^^
  File "D:\Projects\faceswap_rest_api\face_api\venv\Lib\site-packages\urllib3\util\retry.py", line 515, in increment
    raise MaxRetryError(_pool, url, reason) from reason  # type: ignore[arg-type]
    ^^^^^^^^^^^^^^^^^^^^^^^^^^^^^^^^^^^^^^^^^^^^^^^^^^^
urllib3.exceptions.MaxRetryError: HTTPSConnectionPool(host='fs2template.nikb-contact-us.workers.devdata', port=443): Max retries exceeded with url: /source/4.mp4 (Caused by NameResolutionError("<urllib3.connection.HTTPSConnection object at 0x000001C618BF3210>: Failed to resolve 'fs2template.nikb-contact-us.workers.devdata' ([Errno 11001] getaddrinfo failed)"))

During handling of the above exception, another exception occurred:

Traceback (most recent call last):
  File "D:\Projects\faceswap_rest_api\face_api\venv\Lib\site-packages\django\core\handlers\exception.py", line 55, in inner
    response = get_response(request)
               ^^^^^^^^^^^^^^^^^^^^^
  File "D:\Projects\faceswap_rest_api\face_api\venv\Lib\site-packages\django\core\handlers\base.py", line 197, in _get_response
    response = wrapped_callback(request, *callback_args, **callback_kwargs)
               ^^^^^^^^^^^^^^^^^^^^^^^^^^^^^^^^^^^^^^^^^^^^^^^^^^^^^^^^^^^^
  File "D:\Projects\faceswap_rest_api\face_api\venv\Lib\site-packages\django\views\decorators\csrf.py", line 65, in _view_wrapper
    return view_func(request, *args, **kwargs)
           ^^^^^^^^^^^^^^^^^^^^^^^^^^^^^^^^^^^
  File "D:\Projects\faceswap_rest_api\face_api\venv\Lib\site-packages\django\views\generic\base.py", line 104, in view
    return self.dispatch(request, *args, **kwargs)
           ^^^^^^^^^^^^^^^^^^^^^^^^^^^^^^^^^^^^^^^
  File "D:\Projects\faceswap_rest_api\face_api\venv\Lib\site-packages\rest_framework\views.py", line 509, in dispatch
    response = self.handle_exception(exc)
               ^^^^^^^^^^^^^^^^^^^^^^^^^^
  File "D:\Projects\faceswap_rest_api\face_api\venv\Lib\site-packages\rest_framework\views.py", line 469, in handle_exception
    self.raise_uncaught_exception(exc)
  File "D:\Projects\faceswap_rest_api\face_api\venv\Lib\site-packages\rest_framework\views.py", line 480, in raise_uncaught_exception
    raise exc
  File "D:\Projects\faceswap_rest_api\face_api\venv\Lib\site-packages\rest_framework\views.py", line 506, in dispatch
    response = handler(request, *args, **kwargs)
               ^^^^^^^^^^^^^^^^^^^^^^^^^^^^^^^^^
  File "D:\Projects\faceswap_rest_api\face_api\venv\Lib\site-packages\rest_framework\decorators.py", line 50, in handler
    return func(*args, **kwargs)
           ^^^^^^^^^^^^^^^^^^^^^
  File "D:\Projects\faceswap_rest_api\face_api\node\views.py", line 330, in post_template
    CDN_OBJ.upload_to_cdn(re.sub(r'^(\.\/)', '', decode_source_path))
  File "D:\Projects\faceswap_rest_api\face_api\node\cdn_manager.py", line 52, in upload_to_cdn
    response = requests.put(
               ^^^^^^^^^^^^^
  File "D:\Projects\faceswap_rest_api\face_api\venv\Lib\site-packages\requests\api.py", line 130, in put
    return request("put", url, data=data, **kwargs)
           ^^^^^^^^^^^^^^^^^^^^^^^^^^^^^^^^^^^^^^^^
  File "D:\Projects\faceswap_rest_api\face_api\venv\Lib\site-packages\requests\api.py", line 59, in request
    return session.request(method=method, url=url, **kwargs)
           ^^^^^^^^^^^^^^^^^^^^^^^^^^^^^^^^^^^^^^^^^^^^^^^^^
  File "D:\Projects\faceswap_rest_api\face_api\venv\Lib\site-packages\requests\sessions.py", line 589, in request
    resp = self.send(prep, **send_kwargs)
           ^^^^^^^^^^^^^^^^^^^^^^^^^^^^^^
  File "D:\Projects\faceswap_rest_api\face_api\venv\Lib\site-packages\requests\sessions.py", line 703, in send
    r = adapter.send(request, **kwargs)
        ^^^^^^^^^^^^^^^^^^^^^^^^^^^^^^^
  File "D:\Projects\faceswap_rest_api\face_api\venv\Lib\site-packages\requests\adapters.py", line 519, in send
    raise ConnectionError(e, request=request)
requests.exceptions.ConnectionError: HTTPSConnectionPool(host='fs2template.nikb-contact-us.workers.devdata', port=443): Max retries exceeded with url: /source/4.mp4 (Caused by NameResolutionError("<urllib3.connection.HTTPSConnection object at 0x000001C618BF3210>: Failed to resolve 'fs2template.nikb-contact-us.workers.devdata' ([Errno 11001] getaddrinfo failed)"))
"POST /template/add/ HTTP/1.1" 500 207181
Internal Server Error: /template/add/
Traceback (most recent call last):
  File "D:\Projects\faceswap_rest_api\face_api\venv\Lib\site-packages\urllib3\connection.py", line 198, in _new_conn
    sock = connection.create_connection(
           ^^^^^^^^^^^^^^^^^^^^^^^^^^^^^
  File "D:\Projects\faceswap_rest_api\face_api\venv\Lib\site-packages\urllib3\util\connection.py", line 60, in create_connection
    for res in socket.getaddrinfo(host, port, family, socket.SOCK_STREAM):
               ^^^^^^^^^^^^^^^^^^^^^^^^^^^^^^^^^^^^^^^^^^^^^^^^^^^^^^^^^^
  File "C:\Users\Volodia\AppData\Local\Programs\Python\Python311\Lib\socket.py", line 962, in getaddrinfo
    for res in _socket.getaddrinfo(host, port, family, type, proto, flags):
               ^^^^^^^^^^^^^^^^^^^^^^^^^^^^^^^^^^^^^^^^^^^^^^^^^^^^^^^^^^^
socket.gaierror: [Errno 11001] getaddrinfo failed

The above exception was the direct cause of the following exception:

Traceback (most recent call last):
  File "D:\Projects\faceswap_rest_api\face_api\venv\Lib\site-packages\urllib3\connectionpool.py", line 793, in urlopen
    response = self._make_request(
               ^^^^^^^^^^^^^^^^^^^
  File "D:\Projects\faceswap_rest_api\face_api\venv\Lib\site-packages\urllib3\connectionpool.py", line 491, in _make_request
    raise new_e
  File "D:\Projects\faceswap_rest_api\face_api\venv\Lib\site-packages\urllib3\connectionpool.py", line 467, in _make_request
    self._validate_conn(conn)
  File "D:\Projects\faceswap_rest_api\face_api\venv\Lib\site-packages\urllib3\connectionpool.py", line 1099, in _validate_conn
    conn.connect()
  File "D:\Projects\faceswap_rest_api\face_api\venv\Lib\site-packages\urllib3\connection.py", line 616, in connect
    self.sock = sock = self._new_conn()
                       ^^^^^^^^^^^^^^^^
  File "D:\Projects\faceswap_rest_api\face_api\venv\Lib\site-packages\urllib3\connection.py", line 205, in _new_conn
    raise NameResolutionError(self.host, self, e) from e
urllib3.exceptions.NameResolutionError: <urllib3.connection.HTTPSConnection object at 0x000001C61EC7F890>: Failed to resolve 'fs2template.nikb-contact-us.workers.devdata' ([Errno 11001] getaddrinfo failed)

The above exception was the direct cause of the following exception:

Traceback (most recent call last):
  File "D:\Projects\faceswap_rest_api\face_api\venv\Lib\site-packages\requests\adapters.py", line 486, in send
    resp = conn.urlopen(
           ^^^^^^^^^^^^^
  File "D:\Projects\faceswap_rest_api\face_api\venv\Lib\site-packages\urllib3\connectionpool.py", line 847, in urlopen
    retries = retries.increment(
              ^^^^^^^^^^^^^^^^^^
  File "D:\Projects\faceswap_rest_api\face_api\venv\Lib\site-packages\urllib3\util\retry.py", line 515, in increment
    raise MaxRetryError(_pool, url, reason) from reason  # type: ignore[arg-type]
    ^^^^^^^^^^^^^^^^^^^^^^^^^^^^^^^^^^^^^^^^^^^^^^^^^^^
urllib3.exceptions.MaxRetryError: HTTPSConnectionPool(host='fs2template.nikb-contact-us.workers.devdata', port=443): Max retries exceeded with url: /source/4.mp4 (Caused by NameResolutionError("<urllib3.connection.HTTPSConnection object at 0x000001C61EC7F890>: Failed to resolve 'fs2template.nikb-contact-us.workers.devdata' ([Errno 11001] getaddrinfo failed)"))

During handling of the above exception, another exception occurred:

Traceback (most recent call last):
  File "D:\Projects\faceswap_rest_api\face_api\venv\Lib\site-packages\django\core\handlers\exception.py", line 55, in inner
    response = get_response(request)
               ^^^^^^^^^^^^^^^^^^^^^
  File "D:\Projects\faceswap_rest_api\face_api\venv\Lib\site-packages\django\core\handlers\base.py", line 197, in _get_response
    response = wrapped_callback(request, *callback_args, **callback_kwargs)
               ^^^^^^^^^^^^^^^^^^^^^^^^^^^^^^^^^^^^^^^^^^^^^^^^^^^^^^^^^^^^
  File "D:\Projects\faceswap_rest_api\face_api\venv\Lib\site-packages\django\views\decorators\csrf.py", line 65, in _view_wrapper
    return view_func(request, *args, **kwargs)
           ^^^^^^^^^^^^^^^^^^^^^^^^^^^^^^^^^^^
  File "D:\Projects\faceswap_rest_api\face_api\venv\Lib\site-packages\django\views\generic\base.py", line 104, in view
    return self.dispatch(request, *args, **kwargs)
           ^^^^^^^^^^^^^^^^^^^^^^^^^^^^^^^^^^^^^^^
  File "D:\Projects\faceswap_rest_api\face_api\venv\Lib\site-packages\rest_framework\views.py", line 509, in dispatch
    response = self.handle_exception(exc)
               ^^^^^^^^^^^^^^^^^^^^^^^^^^
  File "D:\Projects\faceswap_rest_api\face_api\venv\Lib\site-packages\rest_framework\views.py", line 469, in handle_exception
    self.raise_uncaught_exception(exc)
  File "D:\Projects\faceswap_rest_api\face_api\venv\Lib\site-packages\rest_framework\views.py", line 480, in raise_uncaught_exception
    raise exc
  File "D:\Projects\faceswap_rest_api\face_api\venv\Lib\site-packages\rest_framework\views.py", line 506, in dispatch
    response = handler(request, *args, **kwargs)
               ^^^^^^^^^^^^^^^^^^^^^^^^^^^^^^^^^
  File "D:\Projects\faceswap_rest_api\face_api\venv\Lib\site-packages\rest_framework\decorators.py", line 50, in handler
    return func(*args, **kwargs)
           ^^^^^^^^^^^^^^^^^^^^^
  File "D:\Projects\faceswap_rest_api\face_api\node\views.py", line 330, in post_template
    CDN_OBJ.upload_to_cdn(re.sub(r'^(\.\/)', '', decode_source_path))
  File "D:\Projects\faceswap_rest_api\face_api\node\cdn_manager.py", line 52, in upload_to_cdn
    response = requests.put(
               ^^^^^^^^^^^^^
  File "D:\Projects\faceswap_rest_api\face_api\venv\Lib\site-packages\requests\api.py", line 130, in put
    return request("put", url, data=data, **kwargs)
           ^^^^^^^^^^^^^^^^^^^^^^^^^^^^^^^^^^^^^^^^
  File "D:\Projects\faceswap_rest_api\face_api\venv\Lib\site-packages\requests\api.py", line 59, in request
    return session.request(method=method, url=url, **kwargs)
           ^^^^^^^^^^^^^^^^^^^^^^^^^^^^^^^^^^^^^^^^^^^^^^^^^
  File "D:\Projects\faceswap_rest_api\face_api\venv\Lib\site-packages\requests\sessions.py", line 589, in request
    resp = self.send(prep, **send_kwargs)
           ^^^^^^^^^^^^^^^^^^^^^^^^^^^^^^
  File "D:\Projects\faceswap_rest_api\face_api\venv\Lib\site-packages\requests\sessions.py", line 703, in send
    r = adapter.send(request, **kwargs)
        ^^^^^^^^^^^^^^^^^^^^^^^^^^^^^^^
  File "D:\Projects\faceswap_rest_api\face_api\venv\Lib\site-packages\requests\adapters.py", line 519, in send
    raise ConnectionError(e, request=request)
requests.exceptions.ConnectionError: HTTPSConnectionPool(host='fs2template.nikb-contact-us.workers.devdata', port=443): Max retries exceeded with url: /source/4.mp4 (Caused by NameResolutionError("<urllib3.connection.HTTPSConnection object at 0x000001C61EC7F890>: Failed to resolve 'fs2template.nikb-contact-us.workers.devdata' ([Errno 11001] getaddrinfo failed)"))
"POST /template/add/ HTTP/1.1" 500 207181
Internal Server Error: /template/add/
Traceback (most recent call last):
  File "D:\Projects\faceswap_rest_api\face_api\venv\Lib\site-packages\urllib3\connection.py", line 198, in _new_conn
    sock = connection.create_connection(
           ^^^^^^^^^^^^^^^^^^^^^^^^^^^^^
  File "D:\Projects\faceswap_rest_api\face_api\venv\Lib\site-packages\urllib3\util\connection.py", line 60, in create_connection
    for res in socket.getaddrinfo(host, port, family, socket.SOCK_STREAM):
               ^^^^^^^^^^^^^^^^^^^^^^^^^^^^^^^^^^^^^^^^^^^^^^^^^^^^^^^^^^
  File "C:\Users\Volodia\AppData\Local\Programs\Python\Python311\Lib\socket.py", line 962, in getaddrinfo
    for res in _socket.getaddrinfo(host, port, family, type, proto, flags):
               ^^^^^^^^^^^^^^^^^^^^^^^^^^^^^^^^^^^^^^^^^^^^^^^^^^^^^^^^^^^
socket.gaierror: [Errno 11001] getaddrinfo failed

The above exception was the direct cause of the following exception:

Traceback (most recent call last):
  File "D:\Projects\faceswap_rest_api\face_api\venv\Lib\site-packages\urllib3\connectionpool.py", line 793, in urlopen
    response = self._make_request(
               ^^^^^^^^^^^^^^^^^^^
  File "D:\Projects\faceswap_rest_api\face_api\venv\Lib\site-packages\urllib3\connectionpool.py", line 491, in _make_request
    raise new_e
  File "D:\Projects\faceswap_rest_api\face_api\venv\Lib\site-packages\urllib3\connectionpool.py", line 467, in _make_request
    self._validate_conn(conn)
  File "D:\Projects\faceswap_rest_api\face_api\venv\Lib\site-packages\urllib3\connectionpool.py", line 1099, in _validate_conn
    conn.connect()
  File "D:\Projects\faceswap_rest_api\face_api\venv\Lib\site-packages\urllib3\connection.py", line 616, in connect
    self.sock = sock = self._new_conn()
                       ^^^^^^^^^^^^^^^^
  File "D:\Projects\faceswap_rest_api\face_api\venv\Lib\site-packages\urllib3\connection.py", line 205, in _new_conn
    raise NameResolutionError(self.host, self, e) from e
urllib3.exceptions.NameResolutionError: <urllib3.connection.HTTPSConnection object at 0x000001C618BF1950>: Failed to resolve 'fs2template.nikb-contact-us.workers.devdata' ([Errno 11001] getaddrinfo failed)

The above exception was the direct cause of the following exception:

Traceback (most recent call last):
  File "D:\Projects\faceswap_rest_api\face_api\venv\Lib\site-packages\requests\adapters.py", line 486, in send
    resp = conn.urlopen(
           ^^^^^^^^^^^^^
  File "D:\Projects\faceswap_rest_api\face_api\venv\Lib\site-packages\urllib3\connectionpool.py", line 847, in urlopen
    retries = retries.increment(
              ^^^^^^^^^^^^^^^^^^
  File "D:\Projects\faceswap_rest_api\face_api\venv\Lib\site-packages\urllib3\util\retry.py", line 515, in increment
    raise MaxRetryError(_pool, url, reason) from reason  # type: ignore[arg-type]
    ^^^^^^^^^^^^^^^^^^^^^^^^^^^^^^^^^^^^^^^^^^^^^^^^^^^
urllib3.exceptions.MaxRetryError: HTTPSConnectionPool(host='fs2template.nikb-contact-us.workers.devdata', port=443): Max retries exceeded with url: /source/4.jpg (Caused by NameResolutionError("<urllib3.connection.HTTPSConnection object at 0x000001C618BF1950>: Failed to resolve 'fs2template.nikb-contact-us.workers.devdata' ([Errno 11001] getaddrinfo failed)"))

During handling of the above exception, another exception occurred:

Traceback (most recent call last):
  File "D:\Projects\faceswap_rest_api\face_api\venv\Lib\site-packages\django\core\handlers\exception.py", line 55, in inner
    response = get_response(request)
               ^^^^^^^^^^^^^^^^^^^^^
  File "D:\Projects\faceswap_rest_api\face_api\venv\Lib\site-packages\django\core\handlers\base.py", line 197, in _get_response
    response = wrapped_callback(request, *callback_args, **callback_kwargs)
               ^^^^^^^^^^^^^^^^^^^^^^^^^^^^^^^^^^^^^^^^^^^^^^^^^^^^^^^^^^^^
  File "D:\Projects\faceswap_rest_api\face_api\venv\Lib\site-packages\django\views\decorators\csrf.py", line 65, in _view_wrapper
    return view_func(request, *args, **kwargs)
           ^^^^^^^^^^^^^^^^^^^^^^^^^^^^^^^^^^^
  File "D:\Projects\faceswap_rest_api\face_api\venv\Lib\site-packages\django\views\generic\base.py", line 104, in view
    return self.dispatch(request, *args, **kwargs)
           ^^^^^^^^^^^^^^^^^^^^^^^^^^^^^^^^^^^^^^^
  File "D:\Projects\faceswap_rest_api\face_api\venv\Lib\site-packages\rest_framework\views.py", line 509, in dispatch
    response = self.handle_exception(exc)
               ^^^^^^^^^^^^^^^^^^^^^^^^^^
  File "D:\Projects\faceswap_rest_api\face_api\venv\Lib\site-packages\rest_framework\views.py", line 469, in handle_exception
    self.raise_uncaught_exception(exc)
  File "D:\Projects\faceswap_rest_api\face_api\venv\Lib\site-packages\rest_framework\views.py", line 480, in raise_uncaught_exception
    raise exc
  File "D:\Projects\faceswap_rest_api\face_api\venv\Lib\site-packages\rest_framework\views.py", line 506, in dispatch
    response = handler(request, *args, **kwargs)
               ^^^^^^^^^^^^^^^^^^^^^^^^^^^^^^^^^
  File "D:\Projects\faceswap_rest_api\face_api\venv\Lib\site-packages\rest_framework\decorators.py", line 50, in handler
    return func(*args, **kwargs)
           ^^^^^^^^^^^^^^^^^^^^^
  File "D:\Projects\faceswap_rest_api\face_api\node\views.py", line 330, in post_template
    CDN_OBJ.upload_to_cdn(re.sub(r'^(\.\/)', '', decode_source_path))
  File "D:\Projects\faceswap_rest_api\face_api\node\cdn_manager.py", line 52, in upload_to_cdn
    response = requests.put(
               ^^^^^^^^^^^^^
  File "D:\Projects\faceswap_rest_api\face_api\venv\Lib\site-packages\requests\api.py", line 130, in put
    return request("put", url, data=data, **kwargs)
           ^^^^^^^^^^^^^^^^^^^^^^^^^^^^^^^^^^^^^^^^
  File "D:\Projects\faceswap_rest_api\face_api\venv\Lib\site-packages\requests\api.py", line 59, in request
    return session.request(method=method, url=url, **kwargs)
           ^^^^^^^^^^^^^^^^^^^^^^^^^^^^^^^^^^^^^^^^^^^^^^^^^
  File "D:\Projects\faceswap_rest_api\face_api\venv\Lib\site-packages\requests\sessions.py", line 589, in request
    resp = self.send(prep, **send_kwargs)
           ^^^^^^^^^^^^^^^^^^^^^^^^^^^^^^
  File "D:\Projects\faceswap_rest_api\face_api\venv\Lib\site-packages\requests\sessions.py", line 703, in send
    r = adapter.send(request, **kwargs)
        ^^^^^^^^^^^^^^^^^^^^^^^^^^^^^^^
  File "D:\Projects\faceswap_rest_api\face_api\venv\Lib\site-packages\requests\adapters.py", line 519, in send
    raise ConnectionError(e, request=request)
requests.exceptions.ConnectionError: HTTPSConnectionPool(host='fs2template.nikb-contact-us.workers.devdata', port=443): Max retries exceeded with url: /source/4.jpg (Caused by NameResolutionError("<urllib3.connection.HTTPSConnection object at 0x000001C618BF1950>: Failed to resolve 'fs2template.nikb-contact-us.workers.devdata' ([Errno 11001] getaddrinfo failed)"))
"POST /template/add/ HTTP/1.1" 500 207407
D:\Projects\faceswap_rest_api\face_api\node\views.py changed, reloading.
Watching for file changes with StatReloader
Internal Server Error: /template/add/
Traceback (most recent call last):
  File "D:\Projects\faceswap_rest_api\face_api\venv\Lib\site-packages\django\core\handlers\exception.py", line 55, in inner
    response = get_response(request)
               ^^^^^^^^^^^^^^^^^^^^^
  File "D:\Projects\faceswap_rest_api\face_api\venv\Lib\site-packages\django\core\handlers\base.py", line 197, in _get_response
    response = wrapped_callback(request, *callback_args, **callback_kwargs)
               ^^^^^^^^^^^^^^^^^^^^^^^^^^^^^^^^^^^^^^^^^^^^^^^^^^^^^^^^^^^^
  File "D:\Projects\faceswap_rest_api\face_api\venv\Lib\site-packages\django\views\decorators\csrf.py", line 65, in _view_wrapper
    return view_func(request, *args, **kwargs)
           ^^^^^^^^^^^^^^^^^^^^^^^^^^^^^^^^^^^
  File "D:\Projects\faceswap_rest_api\face_api\venv\Lib\site-packages\django\views\generic\base.py", line 104, in view
    return self.dispatch(request, *args, **kwargs)
           ^^^^^^^^^^^^^^^^^^^^^^^^^^^^^^^^^^^^^^^
  File "D:\Projects\faceswap_rest_api\face_api\venv\Lib\site-packages\rest_framework\views.py", line 509, in dispatch
    response = self.handle_exception(exc)
               ^^^^^^^^^^^^^^^^^^^^^^^^^^
  File "D:\Projects\faceswap_rest_api\face_api\venv\Lib\site-packages\rest_framework\views.py", line 469, in handle_exception
    self.raise_uncaught_exception(exc)
  File "D:\Projects\faceswap_rest_api\face_api\venv\Lib\site-packages\rest_framework\views.py", line 480, in raise_uncaught_exception
    raise exc
  File "D:\Projects\faceswap_rest_api\face_api\venv\Lib\site-packages\rest_framework\views.py", line 506, in dispatch
    response = handler(request, *args, **kwargs)
               ^^^^^^^^^^^^^^^^^^^^^^^^^^^^^^^^^
  File "D:\Projects\faceswap_rest_api\face_api\venv\Lib\site-packages\rest_framework\decorators.py", line 50, in handler
    return func(*args, **kwargs)
           ^^^^^^^^^^^^^^^^^^^^^
  File "D:\Projects\faceswap_rest_api\face_api\node\views.py", line 330, in post_template
    CDN_OBJ.upload_to_cdn(re.sub(r'^(\.)', '', decode_source_path))
  File "D:\Projects\faceswap_rest_api\face_api\node\cdn_manager.py", line 51, in upload_to_cdn
    with open(file_path, "rb") as f:
         ^^^^^^^^^^^^^^^^^^^^^
FileNotFoundError: [Errno 2] No such file or directory: '/data/source/4.jpg'
"POST /template/add/ HTTP/1.1" 500 107886
D:\Projects\faceswap_rest_api\face_api\node\views.py changed, reloading.
Watching for file changes with StatReloader
D:\Projects\faceswap_rest_api\face_api\node\views.py changed, reloading.
Watching for file changes with StatReloader
Internal Server Error: /template/add/
Traceback (most recent call last):
  File "D:\Projects\faceswap_rest_api\face_api\venv\Lib\site-packages\urllib3\connection.py", line 198, in _new_conn
    sock = connection.create_connection(
           ^^^^^^^^^^^^^^^^^^^^^^^^^^^^^
  File "D:\Projects\faceswap_rest_api\face_api\venv\Lib\site-packages\urllib3\util\connection.py", line 60, in create_connection
    for res in socket.getaddrinfo(host, port, family, socket.SOCK_STREAM):
               ^^^^^^^^^^^^^^^^^^^^^^^^^^^^^^^^^^^^^^^^^^^^^^^^^^^^^^^^^^
  File "C:\Users\Volodia\AppData\Local\Programs\Python\Python311\Lib\socket.py", line 962, in getaddrinfo
    for res in _socket.getaddrinfo(host, port, family, type, proto, flags):
               ^^^^^^^^^^^^^^^^^^^^^^^^^^^^^^^^^^^^^^^^^^^^^^^^^^^^^^^^^^^
socket.gaierror: [Errno 11001] getaddrinfo failed

The above exception was the direct cause of the following exception:

Traceback (most recent call last):
  File "D:\Projects\faceswap_rest_api\face_api\venv\Lib\site-packages\urllib3\connectionpool.py", line 793, in urlopen
    response = self._make_request(
               ^^^^^^^^^^^^^^^^^^^
  File "D:\Projects\faceswap_rest_api\face_api\venv\Lib\site-packages\urllib3\connectionpool.py", line 491, in _make_request
    raise new_e
  File "D:\Projects\faceswap_rest_api\face_api\venv\Lib\site-packages\urllib3\connectionpool.py", line 467, in _make_request
    self._validate_conn(conn)
  File "D:\Projects\faceswap_rest_api\face_api\venv\Lib\site-packages\urllib3\connectionpool.py", line 1099, in _validate_conn
    conn.connect()
  File "D:\Projects\faceswap_rest_api\face_api\venv\Lib\site-packages\urllib3\connection.py", line 616, in connect
    self.sock = sock = self._new_conn()
                       ^^^^^^^^^^^^^^^^
  File "D:\Projects\faceswap_rest_api\face_api\venv\Lib\site-packages\urllib3\connection.py", line 205, in _new_conn
    raise NameResolutionError(self.host, self, e) from e
urllib3.exceptions.NameResolutionError: <urllib3.connection.HTTPSConnection object at 0x000001A391E03090>: Failed to resolve 'fs2template.nikb-contact-us.workers.devdata' ([Errno 11001] getaddrinfo failed)

The above exception was the direct cause of the following exception:

Traceback (most recent call last):
  File "D:\Projects\faceswap_rest_api\face_api\venv\Lib\site-packages\requests\adapters.py", line 486, in send
    resp = conn.urlopen(
           ^^^^^^^^^^^^^
  File "D:\Projects\faceswap_rest_api\face_api\venv\Lib\site-packages\urllib3\connectionpool.py", line 847, in urlopen
    retries = retries.increment(
              ^^^^^^^^^^^^^^^^^^
  File "D:\Projects\faceswap_rest_api\face_api\venv\Lib\site-packages\urllib3\util\retry.py", line 515, in increment
    raise MaxRetryError(_pool, url, reason) from reason  # type: ignore[arg-type]
    ^^^^^^^^^^^^^^^^^^^^^^^^^^^^^^^^^^^^^^^^^^^^^^^^^^^
urllib3.exceptions.MaxRetryError: HTTPSConnectionPool(host='fs2template.nikb-contact-us.workers.devdata', port=443): Max retries exceeded with url: /source/4.jpg (Caused by NameResolutionError("<urllib3.connection.HTTPSConnection object at 0x000001A391E03090>: Failed to resolve 'fs2template.nikb-contact-us.workers.devdata' ([Errno 11001] getaddrinfo failed)"))

During handling of the above exception, another exception occurred:

Traceback (most recent call last):
  File "D:\Projects\faceswap_rest_api\face_api\venv\Lib\site-packages\django\core\handlers\exception.py", line 55, in inner
    response = get_response(request)
               ^^^^^^^^^^^^^^^^^^^^^
  File "D:\Projects\faceswap_rest_api\face_api\venv\Lib\site-packages\django\core\handlers\base.py", line 197, in _get_response
    response = wrapped_callback(request, *callback_args, **callback_kwargs)
               ^^^^^^^^^^^^^^^^^^^^^^^^^^^^^^^^^^^^^^^^^^^^^^^^^^^^^^^^^^^^
  File "D:\Projects\faceswap_rest_api\face_api\venv\Lib\site-packages\django\views\decorators\csrf.py", line 65, in _view_wrapper
    return view_func(request, *args, **kwargs)
           ^^^^^^^^^^^^^^^^^^^^^^^^^^^^^^^^^^^
  File "D:\Projects\faceswap_rest_api\face_api\venv\Lib\site-packages\django\views\generic\base.py", line 104, in view
    return self.dispatch(request, *args, **kwargs)
           ^^^^^^^^^^^^^^^^^^^^^^^^^^^^^^^^^^^^^^^
  File "D:\Projects\faceswap_rest_api\face_api\venv\Lib\site-packages\rest_framework\views.py", line 509, in dispatch
    response = self.handle_exception(exc)
               ^^^^^^^^^^^^^^^^^^^^^^^^^^
  File "D:\Projects\faceswap_rest_api\face_api\venv\Lib\site-packages\rest_framework\views.py", line 469, in handle_exception
    self.raise_uncaught_exception(exc)
  File "D:\Projects\faceswap_rest_api\face_api\venv\Lib\site-packages\rest_framework\views.py", line 480, in raise_uncaught_exception
    raise exc
  File "D:\Projects\faceswap_rest_api\face_api\venv\Lib\site-packages\rest_framework\views.py", line 506, in dispatch
    response = handler(request, *args, **kwargs)
               ^^^^^^^^^^^^^^^^^^^^^^^^^^^^^^^^^
  File "D:\Projects\faceswap_rest_api\face_api\venv\Lib\site-packages\rest_framework\decorators.py", line 50, in handler
    return func(*args, **kwargs)
           ^^^^^^^^^^^^^^^^^^^^^
  File "D:\Projects\faceswap_rest_api\face_api\node\views.py", line 330, in post_template
    CDN_OBJ.upload_to_cdn(re.sub(r'^(\.\/)', '', decode_source_path))
  File "D:\Projects\faceswap_rest_api\face_api\node\cdn_manager.py", line 52, in upload_to_cdn
    response = requests.put(
               ^^^^^^^^^^^^^
  File "D:\Projects\faceswap_rest_api\face_api\venv\Lib\site-packages\requests\api.py", line 130, in put
    return request("put", url, data=data, **kwargs)
           ^^^^^^^^^^^^^^^^^^^^^^^^^^^^^^^^^^^^^^^^
  File "D:\Projects\faceswap_rest_api\face_api\venv\Lib\site-packages\requests\api.py", line 59, in request
    return session.request(method=method, url=url, **kwargs)
           ^^^^^^^^^^^^^^^^^^^^^^^^^^^^^^^^^^^^^^^^^^^^^^^^^
  File "D:\Projects\faceswap_rest_api\face_api\venv\Lib\site-packages\requests\sessions.py", line 589, in request
    resp = self.send(prep, **send_kwargs)
           ^^^^^^^^^^^^^^^^^^^^^^^^^^^^^^
  File "D:\Projects\faceswap_rest_api\face_api\venv\Lib\site-packages\requests\sessions.py", line 703, in send
    r = adapter.send(request, **kwargs)
        ^^^^^^^^^^^^^^^^^^^^^^^^^^^^^^^
  File "D:\Projects\faceswap_rest_api\face_api\venv\Lib\site-packages\requests\adapters.py", line 519, in send
    raise ConnectionError(e, request=request)
requests.exceptions.ConnectionError: HTTPSConnectionPool(host='fs2template.nikb-contact-us.workers.devdata', port=443): Max retries exceeded with url: /source/4.jpg (Caused by NameResolutionError("<urllib3.connection.HTTPSConnection object at 0x000001A391E03090>: Failed to resolve 'fs2template.nikb-contact-us.workers.devdata' ([Errno 11001] getaddrinfo failed)"))
"POST /template/add/ HTTP/1.1" 500 207407
D:\Projects\faceswap_rest_api\face_api\node\views.py changed, reloading.
Watching for file changes with StatReloader
D:\Projects\faceswap_rest_api\face_api\node\views.py changed, reloading.
Watching for file changes with StatReloader
"POST /template/add/ HTTP/1.1" 200 45
D:\Projects\faceswap_rest_api\face_api\node\views.py changed, reloading.
Watching for file changes with StatReloader
D:\Projects\faceswap_rest_api\face_api\node\views.py changed, reloading.
Watching for file changes with StatReloader
Internal Server Error: /template/add/
Traceback (most recent call last):
  File "D:\Projects\faceswap_rest_api\face_api\venv\Lib\site-packages\urllib3\connection.py", line 198, in _new_conn
    sock = connection.create_connection(
           ^^^^^^^^^^^^^^^^^^^^^^^^^^^^^
  File "D:\Projects\faceswap_rest_api\face_api\venv\Lib\site-packages\urllib3\util\connection.py", line 60, in create_connection
    for res in socket.getaddrinfo(host, port, family, socket.SOCK_STREAM):
               ^^^^^^^^^^^^^^^^^^^^^^^^^^^^^^^^^^^^^^^^^^^^^^^^^^^^^^^^^^
  File "C:\Users\Volodia\AppData\Local\Programs\Python\Python311\Lib\socket.py", line 962, in getaddrinfo
    for res in _socket.getaddrinfo(host, port, family, type, proto, flags):
               ^^^^^^^^^^^^^^^^^^^^^^^^^^^^^^^^^^^^^^^^^^^^^^^^^^^^^^^^^^^
socket.gaierror: [Errno 11001] getaddrinfo failed

The above exception was the direct cause of the following exception:

Traceback (most recent call last):
  File "D:\Projects\faceswap_rest_api\face_api\venv\Lib\site-packages\urllib3\connectionpool.py", line 793, in urlopen
    response = self._make_request(
               ^^^^^^^^^^^^^^^^^^^
  File "D:\Projects\faceswap_rest_api\face_api\venv\Lib\site-packages\urllib3\connectionpool.py", line 491, in _make_request
    raise new_e
  File "D:\Projects\faceswap_rest_api\face_api\venv\Lib\site-packages\urllib3\connectionpool.py", line 467, in _make_request
    self._validate_conn(conn)
  File "D:\Projects\faceswap_rest_api\face_api\venv\Lib\site-packages\urllib3\connectionpool.py", line 1099, in _validate_conn
    conn.connect()
  File "D:\Projects\faceswap_rest_api\face_api\venv\Lib\site-packages\urllib3\connection.py", line 616, in connect
    self.sock = sock = self._new_conn()
                       ^^^^^^^^^^^^^^^^
  File "D:\Projects\faceswap_rest_api\face_api\venv\Lib\site-packages\urllib3\connection.py", line 205, in _new_conn
    raise NameResolutionError(self.host, self, e) from e
urllib3.exceptions.NameResolutionError: <urllib3.connection.HTTPSConnection object at 0x0000020A3E92F310>: Failed to resolve 'fs2template.nikb-contact-us.workers.devdata' ([Errno 11001] getaddrinfo failed)

The above exception was the direct cause of the following exception:

Traceback (most recent call last):
  File "D:\Projects\faceswap_rest_api\face_api\venv\Lib\site-packages\requests\adapters.py", line 486, in send
    resp = conn.urlopen(
           ^^^^^^^^^^^^^
  File "D:\Projects\faceswap_rest_api\face_api\venv\Lib\site-packages\urllib3\connectionpool.py", line 847, in urlopen
    retries = retries.increment(
              ^^^^^^^^^^^^^^^^^^
  File "D:\Projects\faceswap_rest_api\face_api\venv\Lib\site-packages\urllib3\util\retry.py", line 515, in increment
    raise MaxRetryError(_pool, url, reason) from reason  # type: ignore[arg-type]
    ^^^^^^^^^^^^^^^^^^^^^^^^^^^^^^^^^^^^^^^^^^^^^^^^^^^
urllib3.exceptions.MaxRetryError: HTTPSConnectionPool(host='fs2template.nikb-contact-us.workers.devdata', port=443): Max retries exceeded with url: /source/5.jpg (Caused by NameResolutionError("<urllib3.connection.HTTPSConnection object at 0x0000020A3E92F310>: Failed to resolve 'fs2template.nikb-contact-us.workers.devdata' ([Errno 11001] getaddrinfo failed)"))

During handling of the above exception, another exception occurred:

Traceback (most recent call last):
  File "D:\Projects\faceswap_rest_api\face_api\venv\Lib\site-packages\django\core\handlers\exception.py", line 55, in inner
    response = get_response(request)
               ^^^^^^^^^^^^^^^^^^^^^
  File "D:\Projects\faceswap_rest_api\face_api\venv\Lib\site-packages\django\core\handlers\base.py", line 197, in _get_response
    response = wrapped_callback(request, *callback_args, **callback_kwargs)
               ^^^^^^^^^^^^^^^^^^^^^^^^^^^^^^^^^^^^^^^^^^^^^^^^^^^^^^^^^^^^
  File "D:\Projects\faceswap_rest_api\face_api\venv\Lib\site-packages\django\views\decorators\csrf.py", line 65, in _view_wrapper
    return view_func(request, *args, **kwargs)
           ^^^^^^^^^^^^^^^^^^^^^^^^^^^^^^^^^^^
  File "D:\Projects\faceswap_rest_api\face_api\venv\Lib\site-packages\django\views\generic\base.py", line 104, in view
    return self.dispatch(request, *args, **kwargs)
           ^^^^^^^^^^^^^^^^^^^^^^^^^^^^^^^^^^^^^^^
  File "D:\Projects\faceswap_rest_api\face_api\venv\Lib\site-packages\rest_framework\views.py", line 509, in dispatch
    response = self.handle_exception(exc)
               ^^^^^^^^^^^^^^^^^^^^^^^^^^
  File "D:\Projects\faceswap_rest_api\face_api\venv\Lib\site-packages\rest_framework\views.py", line 469, in handle_exception
    self.raise_uncaught_exception(exc)
  File "D:\Projects\faceswap_rest_api\face_api\venv\Lib\site-packages\rest_framework\views.py", line 480, in raise_uncaught_exception
    raise exc
  File "D:\Projects\faceswap_rest_api\face_api\venv\Lib\site-packages\rest_framework\views.py", line 506, in dispatch
    response = handler(request, *args, **kwargs)
               ^^^^^^^^^^^^^^^^^^^^^^^^^^^^^^^^^
  File "D:\Projects\faceswap_rest_api\face_api\venv\Lib\site-packages\rest_framework\decorators.py", line 50, in handler
    return func(*args, **kwargs)
           ^^^^^^^^^^^^^^^^^^^^^
  File "D:\Projects\faceswap_rest_api\face_api\node\views.py", line 330, in post_template
    CDN_OBJ.upload_to_cdn(re.sub(r'^(\.\/)', '', decode_source_path))
  File "D:\Projects\faceswap_rest_api\face_api\node\cdn_manager.py", line 52, in upload_to_cdn
    response = requests.put(
               ^^^^^^^^^^^^^
  File "D:\Projects\faceswap_rest_api\face_api\venv\Lib\site-packages\requests\api.py", line 130, in put
    return request("put", url, data=data, **kwargs)
           ^^^^^^^^^^^^^^^^^^^^^^^^^^^^^^^^^^^^^^^^
  File "D:\Projects\faceswap_rest_api\face_api\venv\Lib\site-packages\requests\api.py", line 59, in request
    return session.request(method=method, url=url, **kwargs)
           ^^^^^^^^^^^^^^^^^^^^^^^^^^^^^^^^^^^^^^^^^^^^^^^^^
  File "D:\Projects\faceswap_rest_api\face_api\venv\Lib\site-packages\requests\sessions.py", line 589, in request
    resp = self.send(prep, **send_kwargs)
           ^^^^^^^^^^^^^^^^^^^^^^^^^^^^^^
  File "D:\Projects\faceswap_rest_api\face_api\venv\Lib\site-packages\requests\sessions.py", line 703, in send
    r = adapter.send(request, **kwargs)
        ^^^^^^^^^^^^^^^^^^^^^^^^^^^^^^^
  File "D:\Projects\faceswap_rest_api\face_api\venv\Lib\site-packages\requests\adapters.py", line 519, in send
    raise ConnectionError(e, request=request)
requests.exceptions.ConnectionError: HTTPSConnectionPool(host='fs2template.nikb-contact-us.workers.devdata', port=443): Max retries exceeded with url: /source/5.jpg (Caused by NameResolutionError("<urllib3.connection.HTTPSConnection object at 0x0000020A3E92F310>: Failed to resolve 'fs2template.nikb-contact-us.workers.devdata' ([Errno 11001] getaddrinfo failed)"))
"POST /template/add/ HTTP/1.1" 500 207480
D:\Projects\faceswap_rest_api\face_api\node\views.py changed, reloading.
Watching for file changes with StatReloader
D:\Projects\faceswap_rest_api\face_api\node\views.py changed, reloading.
Watching for file changes with StatReloader
D:\Projects\faceswap_rest_api\face_api\node\views.py changed, reloading.
Watching for file changes with StatReloader
"POST /template/add/ HTTP/1.1" 200 45
"GET /face_get/result?template_id=1 HTTP/1.1" 301 0
"GET /face_get/result/?template_id=1 HTTP/1.1" 200 48
"GET /face_get/result?template_id=2 HTTP/1.1" 301 0
Internal Server Error: /face_get/result/
Traceback (most recent call last):
  File "D:\Projects\faceswap_rest_api\face_api\venv\Lib\site-packages\django\core\handlers\exception.py", line 55, in inner
    response = get_response(request)
               ^^^^^^^^^^^^^^^^^^^^^
  File "D:\Projects\faceswap_rest_api\face_api\venv\Lib\site-packages\django\core\handlers\base.py", line 197, in _get_response
    response = wrapped_callback(request, *callback_args, **callback_kwargs)
               ^^^^^^^^^^^^^^^^^^^^^^^^^^^^^^^^^^^^^^^^^^^^^^^^^^^^^^^^^^^^
  File "D:\Projects\faceswap_rest_api\face_api\venv\Lib\site-packages\django\views\decorators\csrf.py", line 65, in _view_wrapper
    return view_func(request, *args, **kwargs)
           ^^^^^^^^^^^^^^^^^^^^^^^^^^^^^^^^^^^
  File "D:\Projects\faceswap_rest_api\face_api\venv\Lib\site-packages\django\views\generic\base.py", line 104, in view
    return self.dispatch(request, *args, **kwargs)
           ^^^^^^^^^^^^^^^^^^^^^^^^^^^^^^^^^^^^^^^
  File "D:\Projects\faceswap_rest_api\face_api\venv\Lib\site-packages\rest_framework\views.py", line 509, in dispatch
    response = self.handle_exception(exc)
               ^^^^^^^^^^^^^^^^^^^^^^^^^^
  File "D:\Projects\faceswap_rest_api\face_api\venv\Lib\site-packages\rest_framework\views.py", line 469, in handle_exception
    self.raise_uncaught_exception(exc)
  File "D:\Projects\faceswap_rest_api\face_api\venv\Lib\site-packages\rest_framework\views.py", line 480, in raise_uncaught_exception
    raise exc
  File "D:\Projects\faceswap_rest_api\face_api\venv\Lib\site-packages\rest_framework\views.py", line 506, in dispatch
    response = handler(request, *args, **kwargs)
               ^^^^^^^^^^^^^^^^^^^^^^^^^^^^^^^^^
  File "D:\Projects\faceswap_rest_api\face_api\venv\Lib\site-packages\rest_framework\decorators.py", line 50, in handler
    return func(*args, **kwargs)
           ^^^^^^^^^^^^^^^^^^^^^
  File "D:\Projects\faceswap_rest_api\face_api\node\views.py", line 269, in get_faceget_result
    faces_list.append(settings.CDN_UPLOAD_PATH + re.sub(r'^(\.\/)', '', serializer.data['source']))
                                                 ^^
NameError: name 're' is not defined
"GET /face_get/result/?template_id=2 HTTP/1.1" 500 101968
"GET /face_get/result?template_id=3 HTTP/1.1" 301 0
Internal Server Error: /face_get/result/
Traceback (most recent call last):
  File "D:\Projects\faceswap_rest_api\face_api\venv\Lib\site-packages\django\core\handlers\exception.py", line 55, in inner
    response = get_response(request)
               ^^^^^^^^^^^^^^^^^^^^^
  File "D:\Projects\faceswap_rest_api\face_api\venv\Lib\site-packages\django\core\handlers\base.py", line 197, in _get_response
    response = wrapped_callback(request, *callback_args, **callback_kwargs)
               ^^^^^^^^^^^^^^^^^^^^^^^^^^^^^^^^^^^^^^^^^^^^^^^^^^^^^^^^^^^^
  File "D:\Projects\faceswap_rest_api\face_api\venv\Lib\site-packages\django\views\decorators\csrf.py", line 65, in _view_wrapper
    return view_func(request, *args, **kwargs)
           ^^^^^^^^^^^^^^^^^^^^^^^^^^^^^^^^^^^
  File "D:\Projects\faceswap_rest_api\face_api\venv\Lib\site-packages\django\views\generic\base.py", line 104, in view
    return self.dispatch(request, *args, **kwargs)
           ^^^^^^^^^^^^^^^^^^^^^^^^^^^^^^^^^^^^^^^
  File "D:\Projects\faceswap_rest_api\face_api\venv\Lib\site-packages\rest_framework\views.py", line 509, in dispatch
    response = self.handle_exception(exc)
               ^^^^^^^^^^^^^^^^^^^^^^^^^^
  File "D:\Projects\faceswap_rest_api\face_api\venv\Lib\site-packages\rest_framework\views.py", line 469, in handle_exception
    self.raise_uncaught_exception(exc)
  File "D:\Projects\faceswap_rest_api\face_api\venv\Lib\site-packages\rest_framework\views.py", line 480, in raise_uncaught_exception
    raise exc
  File "D:\Projects\faceswap_rest_api\face_api\venv\Lib\site-packages\rest_framework\views.py", line 506, in dispatch
    response = handler(request, *args, **kwargs)
               ^^^^^^^^^^^^^^^^^^^^^^^^^^^^^^^^^
  File "D:\Projects\faceswap_rest_api\face_api\venv\Lib\site-packages\rest_framework\decorators.py", line 50, in handler
    return func(*args, **kwargs)
           ^^^^^^^^^^^^^^^^^^^^^
  File "D:\Projects\faceswap_rest_api\face_api\node\views.py", line 269, in get_faceget_result
    faces_list.append(settings.CDN_UPLOAD_PATH + re.sub(r'^(\.\/)', '', serializer.data['source']))
                                                 ^^
NameError: name 're' is not defined
"GET /face_get/result/?template_id=3 HTTP/1.1" 500 101968
D:\Projects\faceswap_rest_api\face_api\node\views.py changed, reloading.
Watching for file changes with StatReloader
D:\Projects\faceswap_rest_api\face_api\node\views.py changed, reloading.
Watching for file changes with StatReloader
"GET /face_get/result?template_id=3 HTTP/1.1" 301 0
"GET /face_get/result/?template_id=3 HTTP/1.1" 200 123
D:\Projects\faceswap_rest_api\face_api\node\views.py changed, reloading.
Watching for file changes with StatReloader
"GET /face_get/result?template_id=3 HTTP/1.1" 301 0
"GET /face_get/result/?template_id=3 HTTP/1.1" 200 124
D:\Projects\faceswap_rest_api\face_api\node\cdn_manager.py changed, reloading.
Watching for file changes with StatReloader
D:\Projects\faceswap_rest_api\face_api\node\cdn_manager.py changed, reloading.
Watching for file changes with StatReloader
D:\Projects\faceswap_rest_api\face_api\node\cdn_manager.py changed, reloading.
Watching for file changes with StatReloader
D:\Projects\faceswap_rest_api\face_api\node\cdn_manager.py changed, reloading.
Watching for file changes with StatReloader
D:\Projects\faceswap_rest_api\face_api\node\cdn_manager.py changed, reloading.
Watching for file changes with StatReloader
D:\Projects\faceswap_rest_api\face_api\node\cdn_manager.py changed, reloading.
Watching for file changes with StatReloader
Watching for file changes with StatReloader
Watching for file changes with StatReloader
D:\Projects\faceswap_rest_api\face_api\node\cdn_manager.py changed, reloading.
Watching for file changes with StatReloader
D:\Projects\faceswap_rest_api\face_api\node\cdn_manager.py changed, reloading.
Watching for file changes with StatReloader
D:\Projects\faceswap_rest_api\face_api\node\cdn_manager.py changed, reloading.
Watching for file changes with StatReloader
D:\Projects\faceswap_rest_api\face_api\node\cdn_manager.py changed, reloading.
Watching for file changes with StatReloader
"POST /template/add/ HTTP/1.1" 200 46
"GET /face_get/result?template_id=10 HTTP/1.1" 301 0
"GET /face_get/result/?template_id=10 HTTP/1.1" 200 126
"POST /face_swap/ HTTP/1.1" 200 50
"GET /face_swap/result?request_id=7ed698cb-305c-4b1d-9b07-21c1da461546 HTTP/1.1" 301 0
"GET /face_swap/result/?request_id=7ed698cb-305c-4b1d-9b07-21c1da461546 HTTP/1.1" 200 314
"POST /template/add/ HTTP/1.1" 200 46
"GET /face_get/result?template_id=11 HTTP/1.1" 301 0
"GET /face_get/result/?template_id=11 HTTP/1.1" 200 126
"POST /face_swap/ HTTP/1.1" 200 50
"GET /face_swap/result?request_id=a788d882-1adf-4a1d-8eed-e83ee1f4739c HTTP/1.1" 301 0
"GET /face_swap/result/?request_id=a788d882-1adf-4a1d-8eed-e83ee1f4739c HTTP/1.1" 200 321
"GET /face_swap/result?request_id=a788d882-1adf-4a1d-8eed-e83ee1f4739c HTTP/1.1" 301 0
"GET /face_swap/result/?request_id=a788d882-1adf-4a1d-8eed-e83ee1f4739c HTTP/1.1" 200 321
"POST /template/add/ HTTP/1.1" 200 46
"GET /face_get/result?template_id=12 HTTP/1.1" 301 0
"GET /face_get/result/?template_id=12 HTTP/1.1" 200 126
"POST /face_swap/ HTTP/1.1" 200 50
"GET /face_swap/result?request_id=b22bd7b3-faa8-42b3-baef-64b64c2287a0 HTTP/1.1" 301 0
"GET /face_swap/result/?request_id=b22bd7b3-faa8-42b3-baef-64b64c2287a0 HTTP/1.1" 200 317
D:\Projects\faceswap_rest_api\face_api\node\views.py changed, reloading.
Watching for file changes with StatReloader
"POST /face_swap/ HTTP/1.1" 200 50
"GET /face_swap/result?request_id=e7470ac8-ca79-40d1-877a-65e2a7786492 HTTP/1.1" 301 0
"GET /face_swap/result/?request_id=e7470ac8-ca79-40d1-877a-65e2a7786492 HTTP/1.1" 200 318
D:\Projects\faceswap_rest_api\face_api\node\views.py changed, reloading.
Watching for file changes with StatReloader
"GET /face_swap/result?request_id=2889071b-471f-4938-8892-1588b3706752 HTTP/1.1" 301 0
"GET /face_swap/result/?request_id=2889071b-471f-4938-8892-1588b3706752 HTTP/1.1" 200 322
"GET /face_swap/result?request_id=2889071b-471f-4938-8892-1588b3706752 HTTP/1.1" 301 0
"GET /face_swap/result/?request_id=2889071b-471f-4938-8892-1588b3706752 HTTP/1.1" 200 322
"GET /face_swap/result?request_id=2889071b-471f-4938-8892-1588b3706752 HTTP/1.1" 301 0
"GET /face_swap/result/?request_id=2889071b-471f-4938-8892-1588b3706752 HTTP/1.1" 200 322
"GET /face_swap/result?request_id=2889071b-471f-4938-8892-1588b3706752 HTTP/1.1" 301 0
"GET /face_swap/result/?request_id=2889071b-471f-4938-8892-1588b3706752 HTTP/1.1" 200 322
Internal Server Error: /face_swap/
Traceback (most recent call last):
  File "D:\Projects\faceswap_rest_api\face_api\node\views.py", line 34, in post_face_swap
    data = json.loads(request.body)  # Ensure data is JSON
                      ^^^^^^^^^^^^
  File "D:\Projects\faceswap_rest_api\face_api\venv\Lib\site-packages\rest_framework\request.py", line 416, in __getattr__
    return getattr(self._request, attr)
           ^^^^^^^^^^^^^^^^^^^^^^^^^^^^
  File "D:\Projects\faceswap_rest_api\face_api\venv\Lib\site-packages\django\http\request.py", line 338, in body
    raise RequestDataTooBig(
django.core.exceptions.RequestDataTooBig: Request body exceeded settings.DATA_UPLOAD_MAX_MEMORY_SIZE.

During handling of the above exception, another exception occurred:

Traceback (most recent call last):
  File "D:\Projects\faceswap_rest_api\face_api\venv\Lib\site-packages\django\core\handlers\exception.py", line 55, in inner
    response = get_response(request)
               ^^^^^^^^^^^^^^^^^^^^^
  File "D:\Projects\faceswap_rest_api\face_api\venv\Lib\site-packages\django\core\handlers\base.py", line 197, in _get_response
    response = wrapped_callback(request, *callback_args, **callback_kwargs)
               ^^^^^^^^^^^^^^^^^^^^^^^^^^^^^^^^^^^^^^^^^^^^^^^^^^^^^^^^^^^^
  File "D:\Projects\faceswap_rest_api\face_api\venv\Lib\site-packages\django\views\decorators\csrf.py", line 65, in _view_wrapper
    return view_func(request, *args, **kwargs)
           ^^^^^^^^^^^^^^^^^^^^^^^^^^^^^^^^^^^
  File "D:\Projects\faceswap_rest_api\face_api\venv\Lib\site-packages\django\views\generic\base.py", line 104, in view
    return self.dispatch(request, *args, **kwargs)
           ^^^^^^^^^^^^^^^^^^^^^^^^^^^^^^^^^^^^^^^
  File "D:\Projects\faceswap_rest_api\face_api\venv\Lib\site-packages\rest_framework\views.py", line 509, in dispatch
    response = self.handle_exception(exc)
               ^^^^^^^^^^^^^^^^^^^^^^^^^^
  File "D:\Projects\faceswap_rest_api\face_api\venv\Lib\site-packages\rest_framework\views.py", line 469, in handle_exception
    self.raise_uncaught_exception(exc)
  File "D:\Projects\faceswap_rest_api\face_api\venv\Lib\site-packages\rest_framework\views.py", line 480, in raise_uncaught_exception
    raise exc
  File "D:\Projects\faceswap_rest_api\face_api\venv\Lib\site-packages\rest_framework\views.py", line 506, in dispatch
    response = handler(request, *args, **kwargs)
               ^^^^^^^^^^^^^^^^^^^^^^^^^^^^^^^^^
  File "D:\Projects\faceswap_rest_api\face_api\venv\Lib\site-packages\rest_framework\decorators.py", line 50, in handler
    return func(*args, **kwargs)
           ^^^^^^^^^^^^^^^^^^^^^
  File "D:\Projects\faceswap_rest_api\face_api\node\views.py", line 152, in post_face_swap
    if os.path.isdir(decode_img_path):
       ^^^^^^^^^^^^^^^^^^^^^^^^^^^^^^
  File "<frozen genericpath>", line 42, in isdir
TypeError: stat: path should be string, bytes, os.PathLike or integer, not NoneType
"POST /face_swap/ HTTP/1.1" 500 113280
Internal Server Error: /face_swap/
Traceback (most recent call last):
  File "D:\Projects\faceswap_rest_api\face_api\node\views.py", line 34, in post_face_swap
    data = json.loads(request.body)  # Ensure data is JSON
                      ^^^^^^^^^^^^
  File "D:\Projects\faceswap_rest_api\face_api\venv\Lib\site-packages\rest_framework\request.py", line 416, in __getattr__
    return getattr(self._request, attr)
           ^^^^^^^^^^^^^^^^^^^^^^^^^^^^
  File "D:\Projects\faceswap_rest_api\face_api\venv\Lib\site-packages\django\http\request.py", line 338, in body
    raise RequestDataTooBig(
django.core.exceptions.RequestDataTooBig: Request body exceeded settings.DATA_UPLOAD_MAX_MEMORY_SIZE.

During handling of the above exception, another exception occurred:

Traceback (most recent call last):
  File "D:\Projects\faceswap_rest_api\face_api\venv\Lib\site-packages\django\core\handlers\exception.py", line 55, in inner
    response = get_response(request)
               ^^^^^^^^^^^^^^^^^^^^^
  File "D:\Projects\faceswap_rest_api\face_api\venv\Lib\site-packages\django\core\handlers\base.py", line 197, in _get_response
    response = wrapped_callback(request, *callback_args, **callback_kwargs)
               ^^^^^^^^^^^^^^^^^^^^^^^^^^^^^^^^^^^^^^^^^^^^^^^^^^^^^^^^^^^^
  File "D:\Projects\faceswap_rest_api\face_api\venv\Lib\site-packages\django\views\decorators\csrf.py", line 65, in _view_wrapper
    return view_func(request, *args, **kwargs)
           ^^^^^^^^^^^^^^^^^^^^^^^^^^^^^^^^^^^
  File "D:\Projects\faceswap_rest_api\face_api\venv\Lib\site-packages\django\views\generic\base.py", line 104, in view
    return self.dispatch(request, *args, **kwargs)
           ^^^^^^^^^^^^^^^^^^^^^^^^^^^^^^^^^^^^^^^
  File "D:\Projects\faceswap_rest_api\face_api\venv\Lib\site-packages\rest_framework\views.py", line 509, in dispatch
    response = self.handle_exception(exc)
               ^^^^^^^^^^^^^^^^^^^^^^^^^^
  File "D:\Projects\faceswap_rest_api\face_api\venv\Lib\site-packages\rest_framework\views.py", line 469, in handle_exception
    self.raise_uncaught_exception(exc)
  File "D:\Projects\faceswap_rest_api\face_api\venv\Lib\site-packages\rest_framework\views.py", line 480, in raise_uncaught_exception
    raise exc
  File "D:\Projects\faceswap_rest_api\face_api\venv\Lib\site-packages\rest_framework\views.py", line 506, in dispatch
    response = handler(request, *args, **kwargs)
               ^^^^^^^^^^^^^^^^^^^^^^^^^^^^^^^^^
  File "D:\Projects\faceswap_rest_api\face_api\venv\Lib\site-packages\rest_framework\decorators.py", line 50, in handler
    return func(*args, **kwargs)
           ^^^^^^^^^^^^^^^^^^^^^
  File "D:\Projects\faceswap_rest_api\face_api\node\views.py", line 152, in post_face_swap
    if os.path.isdir(decode_img_path):
       ^^^^^^^^^^^^^^^^^^^^^^^^^^^^^^
  File "<frozen genericpath>", line 42, in isdir
TypeError: stat: path should be string, bytes, os.PathLike or integer, not NoneType
"POST /face_swap/ HTTP/1.1" 500 113280
D:\Projects\faceswap_rest_api\face_api\node\views.py changed, reloading.
Watching for file changes with StatReloader
Internal Server Error: /face_swap/
Traceback (most recent call last):
  File "D:\Projects\faceswap_rest_api\face_api\node\views.py", line 34, in post_face_swap
    data = json.loads(request.body)  # Ensure data is JSON
                      ^^^^^^^^^^^^
  File "D:\Projects\faceswap_rest_api\face_api\venv\Lib\site-packages\rest_framework\request.py", line 416, in __getattr__
    return getattr(self._request, attr)
           ^^^^^^^^^^^^^^^^^^^^^^^^^^^^
  File "D:\Projects\faceswap_rest_api\face_api\venv\Lib\site-packages\django\http\request.py", line 338, in body
    raise RequestDataTooBig(
django.core.exceptions.RequestDataTooBig: Request body exceeded settings.DATA_UPLOAD_MAX_MEMORY_SIZE.

During handling of the above exception, another exception occurred:

Traceback (most recent call last):
  File "D:\Projects\faceswap_rest_api\face_api\venv\Lib\site-packages\django\core\handlers\exception.py", line 55, in inner
    response = get_response(request)
               ^^^^^^^^^^^^^^^^^^^^^
  File "D:\Projects\faceswap_rest_api\face_api\venv\Lib\site-packages\django\core\handlers\base.py", line 197, in _get_response
    response = wrapped_callback(request, *callback_args, **callback_kwargs)
               ^^^^^^^^^^^^^^^^^^^^^^^^^^^^^^^^^^^^^^^^^^^^^^^^^^^^^^^^^^^^
  File "D:\Projects\faceswap_rest_api\face_api\venv\Lib\site-packages\django\views\decorators\csrf.py", line 65, in _view_wrapper
    return view_func(request, *args, **kwargs)
           ^^^^^^^^^^^^^^^^^^^^^^^^^^^^^^^^^^^
  File "D:\Projects\faceswap_rest_api\face_api\venv\Lib\site-packages\django\views\generic\base.py", line 104, in view
    return self.dispatch(request, *args, **kwargs)
           ^^^^^^^^^^^^^^^^^^^^^^^^^^^^^^^^^^^^^^^
  File "D:\Projects\faceswap_rest_api\face_api\venv\Lib\site-packages\rest_framework\views.py", line 509, in dispatch
    response = self.handle_exception(exc)
               ^^^^^^^^^^^^^^^^^^^^^^^^^^
  File "D:\Projects\faceswap_rest_api\face_api\venv\Lib\site-packages\rest_framework\views.py", line 469, in handle_exception
    self.raise_uncaught_exception(exc)
  File "D:\Projects\faceswap_rest_api\face_api\venv\Lib\site-packages\rest_framework\views.py", line 480, in raise_uncaught_exception
    raise exc
  File "D:\Projects\faceswap_rest_api\face_api\venv\Lib\site-packages\rest_framework\views.py", line 506, in dispatch
    response = handler(request, *args, **kwargs)
               ^^^^^^^^^^^^^^^^^^^^^^^^^^^^^^^^^
  File "D:\Projects\faceswap_rest_api\face_api\venv\Lib\site-packages\rest_framework\decorators.py", line 50, in handler
    return func(*args, **kwargs)
           ^^^^^^^^^^^^^^^^^^^^^
  File "D:\Projects\faceswap_rest_api\face_api\node\views.py", line 152, in post_face_swap
    if os.path.isdir(decode_img_path):
                     ^^^^^^^^^^^^^^^
UnboundLocalError: cannot access local variable 'decode_img_path' where it is not associated with a value
"POST /face_swap/ HTTP/1.1" 500 111919
D:\Projects\faceswap_rest_api\face_api\node\views.py changed, reloading.
Watching for file changes with StatReloader
D:\Projects\faceswap_rest_api\face_api\node\views.py changed, reloading.
Watching for file changes with StatReloader
Internal Server Error: /face_swap/
"POST /face_swap/ HTTP/1.1" 500 89
D:\Projects\faceswap_rest_api\face_api\node\settings.py changed, reloading.
Watching for file changes with StatReloader
D:\Projects\faceswap_rest_api\face_api\node\settings.py changed, reloading.
Watching for file changes with StatReloader
Internal Server Error: /face_swap/
"POST /face_swap/ HTTP/1.1" 500 86
D:\Projects\faceswap_rest_api\face_api\node\settings.py changed, reloading.
Watching for file changes with StatReloader
"POST /face_swap/ HTTP/1.1" 200 50
"GET /face_swap/result?request_id=45241198-086a-4542-b98e-da1ed972bc5b HTTP/1.1" 301 0
"GET /face_swap/result/?request_id=45241198-086a-4542-b98e-da1ed972bc5b HTTP/1.1" 200 323
Watching for file changes with StatReloader
"POST /face_swap/ HTTP/1.1" 200 50
"GET /face_swap/result?request_id=05d4cf00-50b1-468a-939a-a900854567aa HTTP/1.1" 301 0
"GET /face_swap/result/?request_id=05d4cf00-50b1-468a-939a-a900854567aa HTTP/1.1" 200 322
"GET /face_swap/result?request_id=05d4cf00-50b1-468a-939a-a900854567aa HTTP/1.1" 301 0
"GET /face_swap/result/?request_id=05d4cf00-50b1-468a-939a-a900854567aa HTTP/1.1" 200 322
"POST /face_swap/ HTTP/1.1" 200 50
"GET /face_swap/result?request_id=bf581fdc-12c7-4c56-8cd2-1dd2f35fc8e3 HTTP/1.1" 301 0
"GET /face_swap/result/?request_id=bf581fdc-12c7-4c56-8cd2-1dd2f35fc8e3 HTTP/1.1" 200 323
"GET /face_swap/result?request_id=bf581fdc-12c7-4c56-8cd2-1dd2f35fc8e3 HTTP/1.1" 301 0
"GET /face_swap/result/?request_id=bf581fdc-12c7-4c56-8cd2-1dd2f35fc8e3 HTTP/1.1" 200 323
D:\Projects\faceswap_rest_api\face_api\node\cdn_manager.py changed, reloading.
Watching for file changes with StatReloader
"GET /face_swap/result?request_id=bf581fdc-12c7-4c56-8cd2-1dd2f35fc8e3 HTTP/1.1" 301 0
"GET /face_swap/result/?request_id=bf581fdc-12c7-4c56-8cd2-1dd2f35fc8e3 HTTP/1.1" 200 323
D:\Projects\faceswap_rest_api\face_api\node\cdn_manager.py changed, reloading.
Watching for file changes with StatReloader
D:\Projects\faceswap_rest_api\face_api\node\cdn_manager.py changed, reloading.
Watching for file changes with StatReloader
D:\Projects\faceswap_rest_api\face_api\node\views.py changed, reloading.
Watching for file changes with StatReloader
D:\Projects\faceswap_rest_api\face_api\node\views.py changed, reloading.
Watching for file changes with StatReloader
D:\Projects\faceswap_rest_api\face_api\node\views.py changed, reloading.
Watching for file changes with StatReloader
D:\Projects\faceswap_rest_api\face_api\node\views.py changed, reloading.
Watching for file changes with StatReloader
D:\Projects\faceswap_rest_api\face_api\node\views.py changed, reloading.
Watching for file changes with StatReloader
D:\Projects\faceswap_rest_api\face_api\node\views.py changed, reloading.
Watching for file changes with StatReloader
D:\Projects\faceswap_rest_api\face_api\node\views.py changed, reloading.
Watching for file changes with StatReloader
D:\Projects\faceswap_rest_api\face_api\node\views.py changed, reloading.
Watching for file changes with StatReloader
D:\Projects\faceswap_rest_api\face_api\node\views.py changed, reloading.
Watching for file changes with StatReloader
D:\Projects\faceswap_rest_api\face_api\node\views.py changed, reloading.
Watching for file changes with StatReloader
D:\Projects\faceswap_rest_api\face_api\node\views.py changed, reloading.
Watching for file changes with StatReloader
D:\Projects\faceswap_rest_api\face_api\node\views.py changed, reloading.
Watching for file changes with StatReloader
Watching for file changes with StatReloader
Watching for file changes with StatReloader
Watching for file changes with StatReloader
Watching for file changes with StatReloader
Watching for file changes with StatReloader
Not Found: /check/faces/
"POST /check/faces/ HTTP/1.1" 404 2922
Not Found: /check/faces/
"POST /check/faces/ HTTP/1.1" 404 2922
Not Found: /check/faces/
"POST /check/faces/ HTTP/1.1" 404 2922
Internal Server Error: /check/faces
"POST /check/faces HTTP/1.1" 500 68
Not Found: /check/faces/
"POST /check/faces/ HTTP/1.1" 404 2922
Not Found: /check/faces/
"POST /check/faces/ HTTP/1.1" 404 2922
Internal Server Error: /check/faces
"POST /check/faces HTTP/1.1" 500 68
"POST /check/faces HTTP/1.1" 200 11
Not Found: /check/faces/
"POST /check/faces/ HTTP/1.1" 404 2922
"POST /check/faces HTTP/1.1" 200 11
"POST /check/faces HTTP/1.1" 200 11
Internal Server Error: /template/add
Traceback (most recent call last):
  File "D:\Projects\faceswap_rest_api\face_api\venv\Lib\site-packages\django\core\handlers\exception.py", line 55, in inner
    response = get_response(request)
               ^^^^^^^^^^^^^^^^^^^^^
  File "D:\Projects\faceswap_rest_api\face_api\venv\Lib\site-packages\django\utils\deprecation.py", line 136, in __call__
    response = self.process_response(request, response)
               ^^^^^^^^^^^^^^^^^^^^^^^^^^^^^^^^^^^^^^^^
  File "D:\Projects\faceswap_rest_api\face_api\venv\Lib\site-packages\django\middleware\common.py", line 108, in process_response
    return self.response_redirect_class(self.get_full_path_with_slash(request))
                                        ^^^^^^^^^^^^^^^^^^^^^^^^^^^^^^^^^^^^^^
  File "D:\Projects\faceswap_rest_api\face_api\venv\Lib\site-packages\django\middleware\common.py", line 87, in get_full_path_with_slash
    raise RuntimeError(
RuntimeError: You called this URL via POST, but the URL doesn't end in a slash and you have APPEND_SLASH set. Django can't redirect to the slash URL while maintaining POST data. Change your form to point to 127.0.0.1:6667/template/add/ (note the trailing slash), or set APPEND_SLASH=False in your Django settings.
"POST /template/add HTTP/1.1" 500 74907
Internal Server Error: /template/add
Traceback (most recent call last):
  File "D:\Projects\faceswap_rest_api\face_api\venv\Lib\site-packages\django\core\handlers\exception.py", line 55, in inner
    response = get_response(request)
               ^^^^^^^^^^^^^^^^^^^^^
  File "D:\Projects\faceswap_rest_api\face_api\venv\Lib\site-packages\django\utils\deprecation.py", line 136, in __call__
    response = self.process_response(request, response)
               ^^^^^^^^^^^^^^^^^^^^^^^^^^^^^^^^^^^^^^^^
  File "D:\Projects\faceswap_rest_api\face_api\venv\Lib\site-packages\django\middleware\common.py", line 108, in process_response
    return self.response_redirect_class(self.get_full_path_with_slash(request))
                                        ^^^^^^^^^^^^^^^^^^^^^^^^^^^^^^^^^^^^^^
  File "D:\Projects\faceswap_rest_api\face_api\venv\Lib\site-packages\django\middleware\common.py", line 87, in get_full_path_with_slash
    raise RuntimeError(
RuntimeError: You called this URL via POST, but the URL doesn't end in a slash and you have APPEND_SLASH set. Django can't redirect to the slash URL while maintaining POST data. Change your form to point to 127.0.0.1:6666/template/add/ (note the trailing slash), or set APPEND_SLASH=False in your Django settings.
"POST /template/add HTTP/1.1" 500 74907
Internal Server Error: /template/add
Traceback (most recent call last):
  File "D:\Projects\faceswap_rest_api\face_api\venv\Lib\site-packages\django\core\handlers\exception.py", line 55, in inner
    response = get_response(request)
               ^^^^^^^^^^^^^^^^^^^^^
  File "D:\Projects\faceswap_rest_api\face_api\venv\Lib\site-packages\django\utils\deprecation.py", line 136, in __call__
    response = self.process_response(request, response)
               ^^^^^^^^^^^^^^^^^^^^^^^^^^^^^^^^^^^^^^^^
  File "D:\Projects\faceswap_rest_api\face_api\venv\Lib\site-packages\django\middleware\common.py", line 108, in process_response
    return self.response_redirect_class(self.get_full_path_with_slash(request))
                                        ^^^^^^^^^^^^^^^^^^^^^^^^^^^^^^^^^^^^^^
  File "D:\Projects\faceswap_rest_api\face_api\venv\Lib\site-packages\django\middleware\common.py", line 87, in get_full_path_with_slash
    raise RuntimeError(
RuntimeError: You called this URL via POST, but the URL doesn't end in a slash and you have APPEND_SLASH set. Django can't redirect to the slash URL while maintaining POST data. Change your form to point to 127.0.0.1:6667/template/add/ (note the trailing slash), or set APPEND_SLASH=False in your Django settings.
"POST /template/add HTTP/1.1" 500 74907
Internal Server Error: /template/add
Traceback (most recent call last):
  File "D:\Projects\faceswap_rest_api\face_api\venv\Lib\site-packages\django\core\handlers\exception.py", line 55, in inner
    response = get_response(request)
               ^^^^^^^^^^^^^^^^^^^^^
  File "D:\Projects\faceswap_rest_api\face_api\venv\Lib\site-packages\django\utils\deprecation.py", line 136, in __call__
    response = self.process_response(request, response)
               ^^^^^^^^^^^^^^^^^^^^^^^^^^^^^^^^^^^^^^^^
  File "D:\Projects\faceswap_rest_api\face_api\venv\Lib\site-packages\django\middleware\common.py", line 108, in process_response
    return self.response_redirect_class(self.get_full_path_with_slash(request))
                                        ^^^^^^^^^^^^^^^^^^^^^^^^^^^^^^^^^^^^^^
  File "D:\Projects\faceswap_rest_api\face_api\venv\Lib\site-packages\django\middleware\common.py", line 87, in get_full_path_with_slash
    raise RuntimeError(
RuntimeError: You called this URL via POST, but the URL doesn't end in a slash and you have APPEND_SLASH set. Django can't redirect to the slash URL while maintaining POST data. Change your form to point to 127.0.0.1:6666/template/add/ (note the trailing slash), or set APPEND_SLASH=False in your Django settings.
"POST /template/add HTTP/1.1" 500 74907
Internal Server Error: /template/add/
Traceback (most recent call last):
  File "D:\Projects\faceswap_rest_api\face_api\venv\Lib\site-packages\django\core\handlers\exception.py", line 55, in inner
    response = get_response(request)
               ^^^^^^^^^^^^^^^^^^^^^
  File "D:\Projects\faceswap_rest_api\face_api\venv\Lib\site-packages\django\core\handlers\base.py", line 197, in _get_response
    response = wrapped_callback(request, *callback_args, **callback_kwargs)
               ^^^^^^^^^^^^^^^^^^^^^^^^^^^^^^^^^^^^^^^^^^^^^^^^^^^^^^^^^^^^
  File "D:\Projects\faceswap_rest_api\face_api\venv\Lib\site-packages\django\views\decorators\csrf.py", line 65, in _view_wrapper
    return view_func(request, *args, **kwargs)
           ^^^^^^^^^^^^^^^^^^^^^^^^^^^^^^^^^^^
  File "D:\Projects\faceswap_rest_api\face_api\venv\Lib\site-packages\django\views\generic\base.py", line 104, in view
    return self.dispatch(request, *args, **kwargs)
           ^^^^^^^^^^^^^^^^^^^^^^^^^^^^^^^^^^^^^^^
  File "D:\Projects\faceswap_rest_api\face_api\venv\Lib\site-packages\rest_framework\views.py", line 509, in dispatch
    response = self.handle_exception(exc)
               ^^^^^^^^^^^^^^^^^^^^^^^^^^
  File "D:\Projects\faceswap_rest_api\face_api\venv\Lib\site-packages\rest_framework\views.py", line 469, in handle_exception
    self.raise_uncaught_exception(exc)
  File "D:\Projects\faceswap_rest_api\face_api\venv\Lib\site-packages\rest_framework\views.py", line 480, in raise_uncaught_exception
    raise exc
  File "D:\Projects\faceswap_rest_api\face_api\venv\Lib\site-packages\rest_framework\views.py", line 506, in dispatch
    response = handler(request, *args, **kwargs)
               ^^^^^^^^^^^^^^^^^^^^^^^^^^^^^^^^^
  File "D:\Projects\faceswap_rest_api\face_api\venv\Lib\site-packages\rest_framework\decorators.py", line 50, in handler
    return func(*args, **kwargs)
           ^^^^^^^^^^^^^^^^^^^^^
  File "D:\Projects\faceswap_rest_api\face_api\node\views.py", line 341, in post_template
    CDN_OBJ.upload_to_cdn(decode_source_path)
  File "D:\Projects\faceswap_rest_api\face_api\node\cdn_manager.py", line 50, in upload_to_cdn
    "Content-Type": file_type,
                    ^^^^^^^^^
UnboundLocalError: cannot access local variable 'file_type' where it is not associated with a value
"POST /template/add/ HTTP/1.1" 500 109223
Internal Server Error: /template/add/
Traceback (most recent call last):
  File "D:\Projects\faceswap_rest_api\face_api\venv\Lib\site-packages\django\core\handlers\exception.py", line 55, in inner
    response = get_response(request)
               ^^^^^^^^^^^^^^^^^^^^^
  File "D:\Projects\faceswap_rest_api\face_api\venv\Lib\site-packages\django\core\handlers\base.py", line 197, in _get_response
    response = wrapped_callback(request, *callback_args, **callback_kwargs)
               ^^^^^^^^^^^^^^^^^^^^^^^^^^^^^^^^^^^^^^^^^^^^^^^^^^^^^^^^^^^^
  File "D:\Projects\faceswap_rest_api\face_api\venv\Lib\site-packages\django\views\decorators\csrf.py", line 65, in _view_wrapper
    return view_func(request, *args, **kwargs)
           ^^^^^^^^^^^^^^^^^^^^^^^^^^^^^^^^^^^
  File "D:\Projects\faceswap_rest_api\face_api\venv\Lib\site-packages\django\views\generic\base.py", line 104, in view
    return self.dispatch(request, *args, **kwargs)
           ^^^^^^^^^^^^^^^^^^^^^^^^^^^^^^^^^^^^^^^
  File "D:\Projects\faceswap_rest_api\face_api\venv\Lib\site-packages\rest_framework\views.py", line 509, in dispatch
    response = self.handle_exception(exc)
               ^^^^^^^^^^^^^^^^^^^^^^^^^^
  File "D:\Projects\faceswap_rest_api\face_api\venv\Lib\site-packages\rest_framework\views.py", line 469, in handle_exception
    self.raise_uncaught_exception(exc)
  File "D:\Projects\faceswap_rest_api\face_api\venv\Lib\site-packages\rest_framework\views.py", line 480, in raise_uncaught_exception
    raise exc
  File "D:\Projects\faceswap_rest_api\face_api\venv\Lib\site-packages\rest_framework\views.py", line 506, in dispatch
    response = handler(request, *args, **kwargs)
               ^^^^^^^^^^^^^^^^^^^^^^^^^^^^^^^^^
  File "D:\Projects\faceswap_rest_api\face_api\venv\Lib\site-packages\rest_framework\decorators.py", line 50, in handler
    return func(*args, **kwargs)
           ^^^^^^^^^^^^^^^^^^^^^
  File "D:\Projects\faceswap_rest_api\face_api\node\views.py", line 341, in post_template
    CDN_OBJ.upload_to_cdn(decode_source_path)
  File "D:\Projects\faceswap_rest_api\face_api\node\cdn_manager.py", line 50, in upload_to_cdn
    "Content-Type": file_type,
                    ^^^^^^^^^
UnboundLocalError: cannot access local variable 'file_type' where it is not associated with a value
"POST /template/add/ HTTP/1.1" 500 109223
Internal Server Error: /template/add/
Traceback (most recent call last):
  File "D:\Projects\faceswap_rest_api\face_api\venv\Lib\site-packages\django\core\handlers\exception.py", line 55, in inner
    response = get_response(request)
               ^^^^^^^^^^^^^^^^^^^^^
  File "D:\Projects\faceswap_rest_api\face_api\venv\Lib\site-packages\django\core\handlers\base.py", line 197, in _get_response
    response = wrapped_callback(request, *callback_args, **callback_kwargs)
               ^^^^^^^^^^^^^^^^^^^^^^^^^^^^^^^^^^^^^^^^^^^^^^^^^^^^^^^^^^^^
  File "D:\Projects\faceswap_rest_api\face_api\venv\Lib\site-packages\django\views\decorators\csrf.py", line 65, in _view_wrapper
    return view_func(request, *args, **kwargs)
           ^^^^^^^^^^^^^^^^^^^^^^^^^^^^^^^^^^^
  File "D:\Projects\faceswap_rest_api\face_api\venv\Lib\site-packages\django\views\generic\base.py", line 104, in view
    return self.dispatch(request, *args, **kwargs)
           ^^^^^^^^^^^^^^^^^^^^^^^^^^^^^^^^^^^^^^^
  File "D:\Projects\faceswap_rest_api\face_api\venv\Lib\site-packages\rest_framework\views.py", line 509, in dispatch
    response = self.handle_exception(exc)
               ^^^^^^^^^^^^^^^^^^^^^^^^^^
  File "D:\Projects\faceswap_rest_api\face_api\venv\Lib\site-packages\rest_framework\views.py", line 469, in handle_exception
    self.raise_uncaught_exception(exc)
  File "D:\Projects\faceswap_rest_api\face_api\venv\Lib\site-packages\rest_framework\views.py", line 480, in raise_uncaught_exception
    raise exc
  File "D:\Projects\faceswap_rest_api\face_api\venv\Lib\site-packages\rest_framework\views.py", line 506, in dispatch
    response = handler(request, *args, **kwargs)
               ^^^^^^^^^^^^^^^^^^^^^^^^^^^^^^^^^
  File "D:\Projects\faceswap_rest_api\face_api\venv\Lib\site-packages\rest_framework\decorators.py", line 50, in handler
    return func(*args, **kwargs)
           ^^^^^^^^^^^^^^^^^^^^^
  File "D:\Projects\faceswap_rest_api\face_api\node\views.py", line 341, in post_template
    CDN_OBJ.upload_to_cdn(decode_source_path)
  File "D:\Projects\faceswap_rest_api\face_api\node\cdn_manager.py", line 50, in upload_to_cdn
    "Content-Type": file_type,
                    ^^^^^^^^^
UnboundLocalError: cannot access local variable 'file_type' where it is not associated with a value
"POST /template/add/ HTTP/1.1" 500 109223
Internal Server Error: /template/add/
Traceback (most recent call last):
  File "D:\Projects\faceswap_rest_api\face_api\venv\Lib\site-packages\django\core\handlers\exception.py", line 55, in inner
    response = get_response(request)
               ^^^^^^^^^^^^^^^^^^^^^
  File "D:\Projects\faceswap_rest_api\face_api\venv\Lib\site-packages\django\core\handlers\base.py", line 197, in _get_response
    response = wrapped_callback(request, *callback_args, **callback_kwargs)
               ^^^^^^^^^^^^^^^^^^^^^^^^^^^^^^^^^^^^^^^^^^^^^^^^^^^^^^^^^^^^
  File "D:\Projects\faceswap_rest_api\face_api\venv\Lib\site-packages\django\views\decorators\csrf.py", line 65, in _view_wrapper
    return view_func(request, *args, **kwargs)
           ^^^^^^^^^^^^^^^^^^^^^^^^^^^^^^^^^^^
  File "D:\Projects\faceswap_rest_api\face_api\venv\Lib\site-packages\django\views\generic\base.py", line 104, in view
    return self.dispatch(request, *args, **kwargs)
           ^^^^^^^^^^^^^^^^^^^^^^^^^^^^^^^^^^^^^^^
  File "D:\Projects\faceswap_rest_api\face_api\venv\Lib\site-packages\rest_framework\views.py", line 509, in dispatch
    response = self.handle_exception(exc)
               ^^^^^^^^^^^^^^^^^^^^^^^^^^
  File "D:\Projects\faceswap_rest_api\face_api\venv\Lib\site-packages\rest_framework\views.py", line 469, in handle_exception
    self.raise_uncaught_exception(exc)
  File "D:\Projects\faceswap_rest_api\face_api\venv\Lib\site-packages\rest_framework\views.py", line 480, in raise_uncaught_exception
    raise exc
  File "D:\Projects\faceswap_rest_api\face_api\venv\Lib\site-packages\rest_framework\views.py", line 506, in dispatch
    response = handler(request, *args, **kwargs)
               ^^^^^^^^^^^^^^^^^^^^^^^^^^^^^^^^^
  File "D:\Projects\faceswap_rest_api\face_api\venv\Lib\site-packages\rest_framework\decorators.py", line 50, in handler
    return func(*args, **kwargs)
           ^^^^^^^^^^^^^^^^^^^^^
  File "D:\Projects\faceswap_rest_api\face_api\node\views.py", line 341, in post_template
    CDN_OBJ.upload_to_cdn(decode_source_path)
  File "D:\Projects\faceswap_rest_api\face_api\node\cdn_manager.py", line 50, in upload_to_cdn
    "Content-Type": file_type,
                    ^^^^^^^^^
UnboundLocalError: cannot access local variable 'file_type' where it is not associated with a value
"POST /template/add/ HTTP/1.1" 500 109223
Internal Server Error: /template/add/
Traceback (most recent call last):
  File "D:\Projects\faceswap_rest_api\face_api\venv\Lib\site-packages\django\core\handlers\exception.py", line 55, in inner
    response = get_response(request)
               ^^^^^^^^^^^^^^^^^^^^^
  File "D:\Projects\faceswap_rest_api\face_api\venv\Lib\site-packages\django\core\handlers\base.py", line 197, in _get_response
    response = wrapped_callback(request, *callback_args, **callback_kwargs)
               ^^^^^^^^^^^^^^^^^^^^^^^^^^^^^^^^^^^^^^^^^^^^^^^^^^^^^^^^^^^^
  File "D:\Projects\faceswap_rest_api\face_api\venv\Lib\site-packages\django\views\decorators\csrf.py", line 65, in _view_wrapper
    return view_func(request, *args, **kwargs)
           ^^^^^^^^^^^^^^^^^^^^^^^^^^^^^^^^^^^
  File "D:\Projects\faceswap_rest_api\face_api\venv\Lib\site-packages\django\views\generic\base.py", line 104, in view
    return self.dispatch(request, *args, **kwargs)
           ^^^^^^^^^^^^^^^^^^^^^^^^^^^^^^^^^^^^^^^
  File "D:\Projects\faceswap_rest_api\face_api\venv\Lib\site-packages\rest_framework\views.py", line 509, in dispatch
    response = self.handle_exception(exc)
               ^^^^^^^^^^^^^^^^^^^^^^^^^^
  File "D:\Projects\faceswap_rest_api\face_api\venv\Lib\site-packages\rest_framework\views.py", line 469, in handle_exception
    self.raise_uncaught_exception(exc)
  File "D:\Projects\faceswap_rest_api\face_api\venv\Lib\site-packages\rest_framework\views.py", line 480, in raise_uncaught_exception
    raise exc
  File "D:\Projects\faceswap_rest_api\face_api\venv\Lib\site-packages\rest_framework\views.py", line 506, in dispatch
    response = handler(request, *args, **kwargs)
               ^^^^^^^^^^^^^^^^^^^^^^^^^^^^^^^^^
  File "D:\Projects\faceswap_rest_api\face_api\venv\Lib\site-packages\rest_framework\decorators.py", line 50, in handler
    return func(*args, **kwargs)
           ^^^^^^^^^^^^^^^^^^^^^
  File "D:\Projects\faceswap_rest_api\face_api\node\views.py", line 341, in post_template
    CDN_OBJ.upload_to_cdn(decode_source_path)
  File "D:\Projects\faceswap_rest_api\face_api\node\cdn_manager.py", line 50, in upload_to_cdn
    "Content-Type": file_type,
                    ^^^^^^^^^
UnboundLocalError: cannot access local variable 'file_type' where it is not associated with a value
"POST /template/add/ HTTP/1.1" 500 109223
Internal Server Error: /template/add/
Traceback (most recent call last):
  File "D:\Projects\faceswap_rest_api\face_api\venv\Lib\site-packages\django\core\handlers\exception.py", line 55, in inner
    response = get_response(request)
               ^^^^^^^^^^^^^^^^^^^^^
  File "D:\Projects\faceswap_rest_api\face_api\venv\Lib\site-packages\django\core\handlers\base.py", line 197, in _get_response
    response = wrapped_callback(request, *callback_args, **callback_kwargs)
               ^^^^^^^^^^^^^^^^^^^^^^^^^^^^^^^^^^^^^^^^^^^^^^^^^^^^^^^^^^^^
  File "D:\Projects\faceswap_rest_api\face_api\venv\Lib\site-packages\django\views\decorators\csrf.py", line 65, in _view_wrapper
    return view_func(request, *args, **kwargs)
           ^^^^^^^^^^^^^^^^^^^^^^^^^^^^^^^^^^^
  File "D:\Projects\faceswap_rest_api\face_api\venv\Lib\site-packages\django\views\generic\base.py", line 104, in view
    return self.dispatch(request, *args, **kwargs)
           ^^^^^^^^^^^^^^^^^^^^^^^^^^^^^^^^^^^^^^^
  File "D:\Projects\faceswap_rest_api\face_api\venv\Lib\site-packages\rest_framework\views.py", line 509, in dispatch
    response = self.handle_exception(exc)
               ^^^^^^^^^^^^^^^^^^^^^^^^^^
  File "D:\Projects\faceswap_rest_api\face_api\venv\Lib\site-packages\rest_framework\views.py", line 469, in handle_exception
    self.raise_uncaught_exception(exc)
  File "D:\Projects\faceswap_rest_api\face_api\venv\Lib\site-packages\rest_framework\views.py", line 480, in raise_uncaught_exception
    raise exc
  File "D:\Projects\faceswap_rest_api\face_api\venv\Lib\site-packages\rest_framework\views.py", line 506, in dispatch
    response = handler(request, *args, **kwargs)
               ^^^^^^^^^^^^^^^^^^^^^^^^^^^^^^^^^
  File "D:\Projects\faceswap_rest_api\face_api\venv\Lib\site-packages\rest_framework\decorators.py", line 50, in handler
    return func(*args, **kwargs)
           ^^^^^^^^^^^^^^^^^^^^^
  File "D:\Projects\faceswap_rest_api\face_api\node\views.py", line 341, in post_template
    CDN_OBJ.upload_to_cdn(decode_source_path)
  File "D:\Projects\faceswap_rest_api\face_api\node\cdn_manager.py", line 50, in upload_to_cdn
    "Content-Type": file_type,
                    ^^^^^^^^^
UnboundLocalError: cannot access local variable 'file_type' where it is not associated with a value
"POST /template/add/ HTTP/1.1" 500 109223
Internal Server Error: /template/add/
Traceback (most recent call last):
  File "D:\Projects\faceswap_rest_api\face_api\venv\Lib\site-packages\django\core\handlers\exception.py", line 55, in inner
    response = get_response(request)
               ^^^^^^^^^^^^^^^^^^^^^
  File "D:\Projects\faceswap_rest_api\face_api\venv\Lib\site-packages\django\core\handlers\base.py", line 197, in _get_response
    response = wrapped_callback(request, *callback_args, **callback_kwargs)
               ^^^^^^^^^^^^^^^^^^^^^^^^^^^^^^^^^^^^^^^^^^^^^^^^^^^^^^^^^^^^
  File "D:\Projects\faceswap_rest_api\face_api\venv\Lib\site-packages\django\views\decorators\csrf.py", line 65, in _view_wrapper
    return view_func(request, *args, **kwargs)
           ^^^^^^^^^^^^^^^^^^^^^^^^^^^^^^^^^^^
  File "D:\Projects\faceswap_rest_api\face_api\venv\Lib\site-packages\django\views\generic\base.py", line 104, in view
    return self.dispatch(request, *args, **kwargs)
           ^^^^^^^^^^^^^^^^^^^^^^^^^^^^^^^^^^^^^^^
  File "D:\Projects\faceswap_rest_api\face_api\venv\Lib\site-packages\rest_framework\views.py", line 509, in dispatch
    response = self.handle_exception(exc)
               ^^^^^^^^^^^^^^^^^^^^^^^^^^
  File "D:\Projects\faceswap_rest_api\face_api\venv\Lib\site-packages\rest_framework\views.py", line 469, in handle_exception
    self.raise_uncaught_exception(exc)
  File "D:\Projects\faceswap_rest_api\face_api\venv\Lib\site-packages\rest_framework\views.py", line 480, in raise_uncaught_exception
    raise exc
  File "D:\Projects\faceswap_rest_api\face_api\venv\Lib\site-packages\rest_framework\views.py", line 506, in dispatch
    response = handler(request, *args, **kwargs)
               ^^^^^^^^^^^^^^^^^^^^^^^^^^^^^^^^^
  File "D:\Projects\faceswap_rest_api\face_api\venv\Lib\site-packages\rest_framework\decorators.py", line 50, in handler
    return func(*args, **kwargs)
           ^^^^^^^^^^^^^^^^^^^^^
  File "D:\Projects\faceswap_rest_api\face_api\node\views.py", line 341, in post_template
    CDN_OBJ.upload_to_cdn(decode_source_path)
  File "D:\Projects\faceswap_rest_api\face_api\node\cdn_manager.py", line 50, in upload_to_cdn
    "Content-Type": file_type,
                    ^^^^^^^^^
UnboundLocalError: cannot access local variable 'file_type' where it is not associated with a value
"POST /template/add/ HTTP/1.1" 500 109223
Internal Server Error: /template/add/
Traceback (most recent call last):
  File "D:\Projects\faceswap_rest_api\face_api\venv\Lib\site-packages\django\core\handlers\exception.py", line 55, in inner
    response = get_response(request)
               ^^^^^^^^^^^^^^^^^^^^^
  File "D:\Projects\faceswap_rest_api\face_api\venv\Lib\site-packages\django\core\handlers\base.py", line 197, in _get_response
    response = wrapped_callback(request, *callback_args, **callback_kwargs)
               ^^^^^^^^^^^^^^^^^^^^^^^^^^^^^^^^^^^^^^^^^^^^^^^^^^^^^^^^^^^^
  File "D:\Projects\faceswap_rest_api\face_api\venv\Lib\site-packages\django\views\decorators\csrf.py", line 65, in _view_wrapper
    return view_func(request, *args, **kwargs)
           ^^^^^^^^^^^^^^^^^^^^^^^^^^^^^^^^^^^
  File "D:\Projects\faceswap_rest_api\face_api\venv\Lib\site-packages\django\views\generic\base.py", line 104, in view
    return self.dispatch(request, *args, **kwargs)
           ^^^^^^^^^^^^^^^^^^^^^^^^^^^^^^^^^^^^^^^
  File "D:\Projects\faceswap_rest_api\face_api\venv\Lib\site-packages\rest_framework\views.py", line 509, in dispatch
    response = self.handle_exception(exc)
               ^^^^^^^^^^^^^^^^^^^^^^^^^^
  File "D:\Projects\faceswap_rest_api\face_api\venv\Lib\site-packages\rest_framework\views.py", line 469, in handle_exception
    self.raise_uncaught_exception(exc)
  File "D:\Projects\faceswap_rest_api\face_api\venv\Lib\site-packages\rest_framework\views.py", line 480, in raise_uncaught_exception
    raise exc
  File "D:\Projects\faceswap_rest_api\face_api\venv\Lib\site-packages\rest_framework\views.py", line 506, in dispatch
    response = handler(request, *args, **kwargs)
               ^^^^^^^^^^^^^^^^^^^^^^^^^^^^^^^^^
  File "D:\Projects\faceswap_rest_api\face_api\venv\Lib\site-packages\rest_framework\decorators.py", line 50, in handler
    return func(*args, **kwargs)
           ^^^^^^^^^^^^^^^^^^^^^
  File "D:\Projects\faceswap_rest_api\face_api\node\views.py", line 341, in post_template
    CDN_OBJ.upload_to_cdn(decode_source_path)
  File "D:\Projects\faceswap_rest_api\face_api\node\cdn_manager.py", line 50, in upload_to_cdn
    "Content-Type": file_type,
                    ^^^^^^^^^
UnboundLocalError: cannot access local variable 'file_type' where it is not associated with a value
"POST /template/add/ HTTP/1.1" 500 109223
"POST /template/add/ HTTP/1.1" 200 46
"POST /template/add/ HTTP/1.1" 200 46
"POST /template/add/ HTTP/1.1" 200 46
"POST /template/add/ HTTP/1.1" 200 46
"POST /template/add/ HTTP/1.1" 200 46
"POST /template/add/ HTTP/1.1" 200 46
Watching for file changes with StatReloader
"POST /template/add/ HTTP/1.1" 200 46
"POST /template/add/ HTTP/1.1" 200 46
"POST /template/add/ HTTP/1.1" 200 46
"POST /template/add/ HTTP/1.1" 200 46
"POST /template/add/ HTTP/1.1" 200 46
"POST /template/add/ HTTP/1.1" 200 46
"POST /template/add/ HTTP/1.1" 200 46
"POST /template/add/ HTTP/1.1" 200 46
D:\Projects\faceswap_rest_api\face_api\node\views.py changed, reloading.
Watching for file changes with StatReloader
Watching for file changes with StatReloader
D:\Projects\faceswap_rest_api\face_api\node\views.py changed, reloading.
D:\Projects\faceswap_rest_api\face_api\node\views.py changed, reloading.
Watching for file changes with StatReloader
Watching for file changes with StatReloader
D:\Projects\faceswap_rest_api\face_api\node\views.py changed, reloading.
D:\Projects\faceswap_rest_api\face_api\node\views.py changed, reloading.
Watching for file changes with StatReloader
Watching for file changes with StatReloader
D:\Projects\faceswap_rest_api\face_api\node\views.py changed, reloading.
Watching for file changes with StatReloader
Watching for file changes with StatReloader
D:\Projects\faceswap_rest_api\face_api\node\views.py changed, reloading.
D:\Projects\faceswap_rest_api\face_api\node\views.py changed, reloading.
Watching for file changes with StatReloader
Watching for file changes with StatReloader
D:\Projects\faceswap_rest_api\face_api\node\views.py changed, reloading.
D:\Projects\faceswap_rest_api\face_api\node\views.py changed, reloading.
Watching for file changes with StatReloader
Watching for file changes with StatReloader
D:\Projects\faceswap_rest_api\face_api\node\views.py changed, reloading.
D:\Projects\faceswap_rest_api\face_api\node\views.py changed, reloading.
Watching for file changes with StatReloader
Watching for file changes with StatReloader
"POST /template/add/ HTTP/1.1" 200 46
D:\Projects\faceswap_rest_api\face_api\node\views.py changed, reloading.
D:\Projects\faceswap_rest_api\face_api\node\views.py changed, reloading.
Watching for file changes with StatReloader
Watching for file changes with StatReloader
D:\Projects\faceswap_rest_api\face_api\node\views.py changed, reloading.
D:\Projects\faceswap_rest_api\face_api\node\views.py changed, reloading.
Watching for file changes with StatReloader
Watching for file changes with StatReloader
D:\Projects\faceswap_rest_api\face_api\node\views.py changed, reloading.
D:\Projects\faceswap_rest_api\face_api\node\views.py changed, reloading.
Watching for file changes with StatReloader
Watching for file changes with StatReloader
D:\Projects\faceswap_rest_api\face_api\node\views.py changed, reloading.
D:\Projects\faceswap_rest_api\face_api\node\views.py changed, reloading.
Watching for file changes with StatReloader
Watching for file changes with StatReloader
D:\Projects\faceswap_rest_api\face_api\node\views.py changed, reloading.
D:\Projects\faceswap_rest_api\face_api\node\views.py changed, reloading.
Watching for file changes with StatReloader
Watching for file changes with StatReloader
D:\Projects\faceswap_rest_api\face_api\node\views.py changed, reloading.
D:\Projects\faceswap_rest_api\face_api\node\views.py changed, reloading.
Watching for file changes with StatReloader
Watching for file changes with StatReloader
D:\Projects\faceswap_rest_api\face_api\node\views.py changed, reloading.
D:\Projects\faceswap_rest_api\face_api\node\views.py changed, reloading.
Watching for file changes with StatReloader
Watching for file changes with StatReloader
"POST /template/add/ HTTP/1.1" 200 46
D:\Projects\faceswap_rest_api\face_api\node\views.py changed, reloading.
D:\Projects\faceswap_rest_api\face_api\node\views.py changed, reloading.
Watching for file changes with StatReloader
Watching for file changes with StatReloader
D:\Projects\faceswap_rest_api\face_api\node\views.py changed, reloading.
D:\Projects\faceswap_rest_api\face_api\node\views.py changed, reloading.
Watching for file changes with StatReloader
Watching for file changes with StatReloader
D:\Projects\faceswap_rest_api\face_api\node\views.py changed, reloading.
Watching for file changes with StatReloader
Internal Server Error: /template/add/
Traceback (most recent call last):
  File "D:\Projects\faceswap_rest_api\face_api\venv\Lib\site-packages\django\core\handlers\exception.py", line 55, in inner
    response = get_response(request)
               ^^^^^^^^^^^^^^^^^^^^^
  File "D:\Projects\faceswap_rest_api\face_api\venv\Lib\site-packages\django\core\handlers\base.py", line 197, in _get_response
    response = wrapped_callback(request, *callback_args, **callback_kwargs)
               ^^^^^^^^^^^^^^^^^^^^^^^^^^^^^^^^^^^^^^^^^^^^^^^^^^^^^^^^^^^^
  File "D:\Projects\faceswap_rest_api\face_api\venv\Lib\site-packages\django\views\decorators\csrf.py", line 65, in _view_wrapper
    return view_func(request, *args, **kwargs)
           ^^^^^^^^^^^^^^^^^^^^^^^^^^^^^^^^^^^
  File "D:\Projects\faceswap_rest_api\face_api\venv\Lib\site-packages\django\views\generic\base.py", line 104, in view
    return self.dispatch(request, *args, **kwargs)
           ^^^^^^^^^^^^^^^^^^^^^^^^^^^^^^^^^^^^^^^
  File "D:\Projects\faceswap_rest_api\face_api\venv\Lib\site-packages\rest_framework\views.py", line 509, in dispatch
    response = self.handle_exception(exc)
               ^^^^^^^^^^^^^^^^^^^^^^^^^^
  File "D:\Projects\faceswap_rest_api\face_api\venv\Lib\site-packages\rest_framework\views.py", line 469, in handle_exception
    self.raise_uncaught_exception(exc)
  File "D:\Projects\faceswap_rest_api\face_api\venv\Lib\site-packages\rest_framework\views.py", line 480, in raise_uncaught_exception
    raise exc
  File "D:\Projects\faceswap_rest_api\face_api\venv\Lib\site-packages\rest_framework\views.py", line 506, in dispatch
    response = handler(request, *args, **kwargs)
               ^^^^^^^^^^^^^^^^^^^^^^^^^^^^^^^^^
  File "D:\Projects\faceswap_rest_api\face_api\venv\Lib\site-packages\rest_framework\decorators.py", line 50, in handler
    return func(*args, **kwargs)
           ^^^^^^^^^^^^^^^^^^^^^
  File "D:\Projects\faceswap_rest_api\face_api\node\views.py", line 306, in post_template
    categories = request.POST.get('category_id').split()
                 ^^^^^^^^^^^^^^^^^^^^^^^^^^^^^^^^^^^^^
AttributeError: 'NoneType' object has no attribute 'split'
"POST /template/add/ HTTP/1.1" 500 101899
D:\Projects\faceswap_rest_api\face_api\node\views.py changed, reloading.
D:\Projects\faceswap_rest_api\face_api\node\views.py changed, reloading.
Watching for file changes with StatReloader
Watching for file changes with StatReloader
"POST /template/add/ HTTP/1.1" 200 46
"POST /template/add/ HTTP/1.1" 200 46
"GET /face_get/result?template_id=44 HTTP/1.1" 301 0
"GET /face_get/result/?template_id=44 HTTP/1.1" 200 49
"GET /face_get/result?template_id=44 HTTP/1.1" 301 0
"GET /face_get/result/?template_id=44 HTTP/1.1" 200 49
"GET /face_get/result?template_id=43 HTTP/1.1" 301 0
"GET /face_get/result/?template_id=43 HTTP/1.1" 200 49
"GET /face_get/result?template_id=32 HTTP/1.1" 301 0
"GET /face_get/result/?template_id=32 HTTP/1.1" 200 49
"GET /face_get/result?template_id=21 HTTP/1.1" 301 0
"GET /face_get/result/?template_id=21 HTTP/1.1" 200 202
"GET /face_get/result?template_id=11 HTTP/1.1" 301 0
"GET /face_get/result/?template_id=11 HTTP/1.1" 200 79
"GET /face_swap/result?request_id=c132684d-318e-47dd-855f-4d4ef6400c7c HTTP/1.1" 301 0
"GET /face_swap/result/?request_id=c132684d-318e-47dd-855f-4d4ef6400c7c HTTP/1.1" 200 316
"GET /face_swap/result?request_id=c132684d-318e-47dd-855f-4d4ef6400c7c HTTP/1.1" 301 0
"GET /face_swap/result/?request_id=c132684d-318e-47dd-855f-4d4ef6400c7c HTTP/1.1" 200 316
"GET /face_get/result?template_id=11 HTTP/1.1" 301 0
"GET /face_get/result/?template_id=11 HTTP/1.1" 200 79
"POST /check/faces HTTP/1.1" 200 11
"POST /check/faces HTTP/1.1" 200 11
Watching for file changes with StatReloader
"POST /check/faces HTTP/1.1" 200 11
Not Found: /queue_status/
"GET /queue_status/ HTTP/1.1" 404 2924
Not Found: /queue_status/
"GET /queue_status/ HTTP/1.1" 404 2924
"GET /queue_status/swapface HTTP/1.1" 301 0
"GET /queue_status/swapface/ HTTP/1.1" 200 33
Internal Server Error: /face_swap
Traceback (most recent call last):
  File "D:\Projects\faceswap_rest_api\face_api\venv\Lib\site-packages\django\core\handlers\exception.py", line 55, in inner
    response = get_response(request)
               ^^^^^^^^^^^^^^^^^^^^^
  File "D:\Projects\faceswap_rest_api\face_api\venv\Lib\site-packages\django\utils\deprecation.py", line 136, in __call__
    response = self.process_response(request, response)
               ^^^^^^^^^^^^^^^^^^^^^^^^^^^^^^^^^^^^^^^^
  File "D:\Projects\faceswap_rest_api\face_api\venv\Lib\site-packages\django\middleware\common.py", line 108, in process_response
    return self.response_redirect_class(self.get_full_path_with_slash(request))
                                        ^^^^^^^^^^^^^^^^^^^^^^^^^^^^^^^^^^^^^^
  File "D:\Projects\faceswap_rest_api\face_api\venv\Lib\site-packages\django\middleware\common.py", line 87, in get_full_path_with_slash
    raise RuntimeError(
RuntimeError: You called this URL via POST, but the URL doesn't end in a slash and you have APPEND_SLASH set. Django can't redirect to the slash URL while maintaining POST data. Change your form to point to 127.0.0.1:6666/face_swap/ (note the trailing slash), or set APPEND_SLASH=False in your Django settings.
"POST /face_swap HTTP/1.1" 500 20744
"GET /queue_status/swapface HTTP/1.1" 301 0
"GET /queue_status/swapface/ HTTP/1.1" 200 33
"POST /face_swap/ HTTP/1.1" 200 50
"GET /queue_status/swapface HTTP/1.1" 301 0
"GET /queue_status/swapface/ HTTP/1.1" 200 33
"POST /face_swap/ HTTP/1.1" 200 50
"GET /queue_status/swapface HTTP/1.1" 301 0
"GET /queue_status/swapface/ HTTP/1.1" 200 33
"POST /face_swap/ HTTP/1.1" 200 50
"GET /queue_status/swapface HTTP/1.1" 301 0
"GET /queue_status/swapface/ HTTP/1.1" 200 33
"POST /face_swap/ HTTP/1.1" 200 50
"GET /face_swap/result?request_id=015b9bf0-76b1-442b-a7f0-ca1f829910af HTTP/1.1" 301 0
"GET /face_swap/result/?request_id=015b9bf0-76b1-442b-a7f0-ca1f829910af HTTP/1.1" 200 316
"GET /face_swap/result?request_id=015b9bf0-76b1-442b-a7f0-ca1f829910af HTTP/1.1" 301 0
"GET /face_swap/result/?request_id=015b9bf0-76b1-442b-a7f0-ca1f829910af HTTP/1.1" 200 316
"GET /face_swap/result?request_id=015b9bf0-76b1-442b-a7f0-ca1f829910af HTTP/1.1" 301 0
"GET /face_swap/result/?request_id=015b9bf0-76b1-442b-a7f0-ca1f829910af HTTP/1.1" 200 316
"GET /face_swap/result?request_id=015b9bf0-76b1-442b-a7f0-ca1f829910af HTTP/1.1" 301 0
"GET /face_swap/result/?request_id=015b9bf0-76b1-442b-a7f0-ca1f829910af HTTP/1.1" 200 316
"GET /face_swap/result?request_id=015b9bf0-76b1-442b-a7f0-ca1f829910af HTTP/1.1" 301 0
"GET /face_swap/result/?request_id=015b9bf0-76b1-442b-a7f0-ca1f829910af HTTP/1.1" 200 316
"GET /face_swap/result?request_id=015b9bf0-76b1-442b-a7f0-ca1f829910af HTTP/1.1" 301 0
"GET /face_swap/result/?request_id=015b9bf0-76b1-442b-a7f0-ca1f829910af HTTP/1.1" 200 316
"GET /face_swap/result?request_id=015b9bf0-76b1-442b-a7f0-ca1f829910af HTTP/1.1" 301 0
"GET /face_swap/result/?request_id=015b9bf0-76b1-442b-a7f0-ca1f829910af HTTP/1.1" 200 316
- Broken pipe from ('127.0.0.1', 53248)
"GET /face_get/result?template_id=11 HTTP/1.1" 301 0
"GET /face_get/result/?template_id=11 HTTP/1.1" 200 79
"GET /face_get/result?template_id=11 HTTP/1.1" 301 0
"GET /face_get/result/?template_id=11 HTTP/1.1" 200 79
"GET /face_get/result?template_id=11 HTTP/1.1" 301 0
"GET /face_get/result/?template_id=11 HTTP/1.1" 200 79
"GET /face_get/result?template_id=19 HTTP/1.1" 301 0
"GET /face_get/result/?template_id=19 HTTP/1.1" 200 110
"GET /face_get/result?template_id=24 HTTP/1.1" 301 0
"GET /face_get/result/?template_id=24 HTTP/1.1" 200 79
"GET /face_get/result?template_id=28 HTTP/1.1" 301 0
"GET /face_get/result/?template_id=28 HTTP/1.1" 200 49
"GET /face_get/result?template_id=34 HTTP/1.1" 301 0
"GET /face_get/result/?template_id=34 HTTP/1.1" 200 49
"GET /face_get/result?template_id=38 HTTP/1.1" 301 0
"GET /face_get/result/?template_id=38 HTTP/1.1" 200 49
"GET /face_get/result?template_id=44 HTTP/1.1" 301 0
"GET /face_get/result/?template_id=44 HTTP/1.1" 200 49
"GET /face_get/result?template_id=38 HTTP/1.1" 301 0
"GET /face_get/result/?template_id=38 HTTP/1.1" 200 49
"GET /face_get/result?template_id=36 HTTP/1.1" 301 0
"GET /face_get/result/?template_id=36 HTTP/1.1" 200 49
"GET /face_get/result?template_id=33 HTTP/1.1" 301 0
"GET /face_get/result/?template_id=33 HTTP/1.1" 200 49
"GET /face_get/result?template_id=32 HTTP/1.1" 301 0
"GET /face_get/result/?template_id=32 HTTP/1.1" 200 49
"GET /face_get/result?template_id=31 HTTP/1.1" 301 0
"GET /face_get/result/?template_id=31 HTTP/1.1" 200 49
"GET /face_get/result?template_id=30 HTTP/1.1" 301 0
"GET /face_get/result/?template_id=30 HTTP/1.1" 200 49
"GET /face_get/result?template_id=28 HTTP/1.1" 301 0
"GET /face_get/result/?template_id=28 HTTP/1.1" 200 49
"GET /face_get/result?template_id=26 HTTP/1.1" 301 0
"GET /face_get/result/?template_id=26 HTTP/1.1" 200 360
"GET /queue_status/swapface HTTP/1.1" 301 0
"GET /queue_status/swapface/ HTTP/1.1" 200 33
"POST /face_swap/ HTTP/1.1" 200 50
- Broken pipe from ('127.0.0.1', 59801)
Watching for file changes with StatReloader
Watching for file changes with StatReloader
"POST /template/add/ HTTP/1.1" 200 46
"POST /template/add/ HTTP/1.1" 200 46
"POST /template/add/ HTTP/1.1" 200 46
Watching for file changes with StatReloader
"POST /template/add/ HTTP/1.1" 200 46
"POST /template/add/ HTTP/1.1" 200 46
"POST /template/add/ HTTP/1.1" 200 46
"POST /template/add/ HTTP/1.1" 200 46
"POST /template/add/ HTTP/1.1" 200 46
"POST /template/add/ HTTP/1.1" 200 46
"POST /template/add/ HTTP/1.1" 200 46
- Broken pipe from ('127.0.0.1', 3321)
